Workbook

Sheet TRACKER
F2: CATEGORY | V2: GRAPHIC STATUS | AI2: DATASET STATUS
E3: TOTAL Charts | F3: {=TRANSPOSE(Validation!A2:A6)} -> Infographic WITHOUT Data | G3: Infographic WITH Data | H3: Chart to recreate | I3: Chart for Direct Use | J3: Maps to recreate | K3: Uncategorized | N3: {=TRANSPOSE(Validation!I2:I6)} -> Pending | O3: In process | P3: Not supported by pipeline | Q3: Ready | R3: Deleted | T3: Unclear | V3: {=TRANSPOSE(Validation!I2:I9)} -> #VALUE! | Z3: Unclear | AC3: {=TRANSPOSE(Validation!I2:I9)} -> #VALUE! | AG3: Unclear | AI3: {=TRANSPOSE(Validation!I2:I9)} -> #VALUE! | AM3: Unclear
B4: Module1 | C4: =_xlfn.CONCAT($B4,"!B3:B100") -> Module1!B3:B100 | D4: =_xlfn.CONCAT($B4,"!N3:N100") -> Module1!N3:N100 | E4: =COUNTA(INDIRECT(C4)) -> 35 | F4: =COUNTIF(INDIRECT($D4),F$3) -> 0 | G4: =COUNTIF(INDIRECT($D4),G$3) -> 2 | H4: =COUNTIF(INDIRECT($D4),H$3) -> 25 | I4: =COUNTIF(INDIRECT($D4),I$3) -> 6 | J4: =COUNTIF(INDIRECT($D4),J$3) -> 2 | K4: =E4-SUM(F4:J4) -> 0 | M4: =_xlfn.CONCAT($B4,"!I3:I100") -> Module1!I3:I100 | N4: =COUNTIF(INDIRECT($M4),N$3) -> 0 | O4: =COUNTIF(INDIRECT($M4),O$3) -> 0 | P4: =COUNTIF(INDIRECT($M4),P$3) -> 0 | Q4: =COUNTIF(INDIRECT($M4),Q$3) -> 0 | T4: =(E4-SUM(N4:Q4)) -> 35 | V4: =N4/$E4 -> 0 | W4: =O4/$E4 -> 0 | X4: =P4/$E4 -> 0 | Y4: =Q4/$E4 -> 0 | Z4: =T4/$E4 -> 1 | AB4: =_xlfn.CONCAT($B4,"!p3:p100") -> Module1!p3:p100 | AC4: =COUNTIF(INDIRECT($AB4),AC$3) -> 0 | AD4: =COUNTIF(INDIRECT($AB4),AD$3) -> 0 | AE4: =COUNTIF(INDIRECT($AB4),AE$3) -> 0 | AF4: =COUNTIF(INDIRECT($AB4),AF$3) -> 0 | AG4: =(H4-SUM(AC4:AF4)) -> 25 | AI4: =AC4/$H4 -> 0 | AJ4: =AD4/$H4 -> 0 | AK4: =AE4/$H4 -> 0 | AL4: =AF4/$H4 -> 0 | AM4: =AG4/$H4 -> 1
B5: Module2 | C5: =_xlfn.CONCAT($B5,"!B3:B100") -> Module2!B3:B100 | D5: =_xlfn.CONCAT($B5,"!N3:N100") -> Module2!N3:N100 | E5: =COUNTA(INDIRECT(C5)) -> 35 | F5: =COUNTIF(INDIRECT($D5),F$3) -> 0 | G5: =COUNTIF(INDIRECT($D5),G$3) -> 0 | H5: =COUNTIF(INDIRECT($D5),H$3) -> 25 | I5: =COUNTIF(INDIRECT($D5),I$3) -> 7 | J5: =COUNTIF(INDIRECT($D5),J$3) -> 1 | K5: =E5-SUM(F5:J5) -> 2 | M5: =_xlfn.CONCAT($B5,"!I3:I100") -> Module2!I3:I100 | N5: =COUNTIF(INDIRECT($M5),N$3) -> 0 | O5: =COUNTIF(INDIRECT($M5),O$3) -> 0 | P5: =COUNTIF(INDIRECT($M5),P$3) -> 0 | Q5: =COUNTIF(INDIRECT($M5),Q$3) -> 0 | T5: =(E5-SUM(N5:Q5)) -> 35 | V5: =N5/$E5 -> 0 | W5: =O5/$E5 -> 0 | X5: =P5/$E5 -> 0 | Y5: =Q5/$E5 -> 0 | Z5: =T5/$E5 -> 1 | AB5: =_xlfn.CONCAT($B5,"!p3:p100") -> Module2!p3:p100 | AC5: =COUNTIF(INDIRECT($AB5),AC$3) -> 0 | AD5: =COUNTIF(INDIRECT($AB5),AD$3) -> 0 | AE5: =COUNTIF(INDIRECT($AB5),AE$3) -> 0 | AF5: =COUNTIF(INDIRECT($AB5),AF$3) -> 0 | AG5: =(H5-SUM(AC5:AF5)) -> 25 | AI5: =AC5/$H5 -> 0 | AJ5: =AD5/$H5 -> 0 | AK5: =AE5/$H5 -> 0 | AL5: =AF5/$H5 -> 0 | AM5: =AG5/$H5 -> 1
B6: Module3 | C6: =_xlfn.CONCAT($B6,"!B3:B100") -> Module3!B3:B100 | D6: =_xlfn.CONCAT($B6,"!N3:N100") -> Module3!N3:N100 | E6: =COUNTA(INDIRECT(C6)) -> 12 | F6: =COUNTIF(INDIRECT($D6),F$3) -> 0 | G6: =COUNTIF(INDIRECT($D6),G$3) -> 0 | H6: =COUNTIF(INDIRECT($D6),H$3) -> 10 | I6: =COUNTIF(INDIRECT($D6),I$3) -> 2 | J6: =COUNTIF(INDIRECT($D6),J$3) -> 0 | K6: =E6-SUM(F6:J6) -> 0 | M6: =_xlfn.CONCAT($B6,"!I3:I100") -> Module3!I3:I100 | N6: =COUNTIF(INDIRECT($M6),N$3) -> 0 | O6: =COUNTIF(INDIRECT($M6),O$3) -> 0 | P6: =COUNTIF(INDIRECT($M6),P$3) -> 0 | Q6: =COUNTIF(INDIRECT($M6),Q$3) -> 0 | T6: =(E6-SUM(N6:Q6)) -> 12 | V6: =N6/$E6 -> 0 | W6: =O6/$E6 -> 0 | X6: =P6/$E6 -> 0 | Y6: =Q6/$E6 -> 0 | Z6: =T6/$E6 -> 1 | AB6: =_xlfn.CONCAT($B6,"!p3:p100") -> Module3!p3:p100 | AC6: =COUNTIF(INDIRECT($AB6),AC$3) -> 0 | AD6: =COUNTIF(INDIRECT($AB6),AD$3) -> 0 | AE6: =COUNTIF(INDIRECT($AB6),AE$3) -> 0 | AF6: =COUNTIF(INDIRECT($AB6),AF$3) -> 0 | AG6: =(H6-SUM(AC6:AF6)) -> 10 | AI6: =AC6/$H6 -> 0 | AJ6: =AD6/$H6 -> 0 | AK6: =AE6/$H6 -> 0 | AL6: =AF6/$H6 -> 0 | AM6: =AG6/$H6 -> 1
B7: Module4 | C7: =_xlfn.CONCAT($B7,"!B3:B100") -> Module4!B3:B100 | D7: =_xlfn.CONCAT($B7,"!N3:N100") -> Module4!N3:N100 | E7: =COUNTA(INDIRECT(C7)) -> 14 | F7: =COUNTIF(INDIRECT($D7),F$3) -> 0 | G7: =COUNTIF(INDIRECT($D7),G$3) -> 0 | H7: =COUNTIF(INDIRECT($D7),H$3) -> 13 | I7: =COUNTIF(INDIRECT($D7),I$3) -> 1 | J7: =COUNTIF(INDIRECT($D7),J$3) -> 0 | K7: =E7-SUM(F7:J7) -> 0 | M7: =_xlfn.CONCAT($B7,"!I3:I100") -> Module4!I3:I100 | N7: =COUNTIF(INDIRECT($M7),N$3) -> 0 | O7: =COUNTIF(INDIRECT($M7),O$3) -> 0 | P7: =COUNTIF(INDIRECT($M7),P$3) -> 0 | Q7: =COUNTIF(INDIRECT($M7),Q$3) -> 0 | T7: =(E7-SUM(N7:Q7)) -> 14 | V7: =N7/$E7 -> 0 | W7: =O7/$E7 -> 0 | X7: =P7/$E7 -> 0 | Y7: =Q7/$E7 -> 0 | Z7: =T7/$E7 -> 1 | AB7: =_xlfn.CONCAT($B7,"!p3:p100") -> Module4!p3:p100 | AC7: =COUNTIF(INDIRECT($AB7),AC$3) -> 0 | AD7: =COUNTIF(INDIRECT($AB7),AD$3) -> 0 | AE7: =COUNTIF(INDIRECT($AB7),AE$3) -> 0 | AF7: =COUNTIF(INDIRECT($AB7),AF$3) -> 0 | AG7: =(H7-SUM(AC7:AF7)) -> 13 | AI7: =AC7/$H7 -> 0 | AJ7: =AD7/$H7 -> 0 | AK7: =AE7/$H7 -> 0 | AL7: =AF7/$H7 -> 0 | AM7: =AG7/$H7 -> 1
B8: Module5 | C8: =_xlfn.CONCAT($B8,"!B3:B100") -> Module5!B3:B100 | D8: =_xlfn.CONCAT($B8,"!N3:N100") -> Module5!N3:N100 | E8: =COUNTA(INDIRECT(C8)) -> 4 | F8: =COUNTIF(INDIRECT($D8),F$3) -> 0 | G8: =COUNTIF(INDIRECT($D8),G$3) -> 0 | H8: =COUNTIF(INDIRECT($D8),H$3) -> 4 | I8: =COUNTIF(INDIRECT($D8),I$3) -> 0 | J8: =COUNTIF(INDIRECT($D8),J$3) -> 0 | K8: =E8-SUM(F8:J8) -> 0 | M8: =_xlfn.CONCAT($B8,"!I3:I100") -> Module5!I3:I100 | N8: =COUNTIF(INDIRECT($M8),N$3) -> 0 | O8: =COUNTIF(INDIRECT($M8),O$3) -> 0 | P8: =COUNTIF(INDIRECT($M8),P$3) -> 0 | Q8: =COUNTIF(INDIRECT($M8),Q$3) -> 0 | T8: =(E8-SUM(N8:Q8)) -> 4 | V8: =N8/$E8 -> 0 | W8: =O8/$E8 -> 0 | X8: =P8/$E8 -> 0 | Y8: =Q8/$E8 -> 0 | Z8: =T8/$E8 -> 1 | AB8: =_xlfn.CONCAT($B8,"!p3:p100") -> Module5!p3:p100 | AC8: =COUNTIF(INDIRECT($AB8),AC$3) -> 0 | AD8: =COUNTIF(INDIRECT($AB8),AD$3) -> 0 | AE8: =COUNTIF(INDIRECT($AB8),AE$3) -> 0 | AF8: =COUNTIF(INDIRECT($AB8),AF$3) -> 0 | AG8: =(H8-SUM(AC8:AF8)) -> 4 | AI8: =AC8/$H8 -> 0 | AJ8: =AD8/$H8 -> 0 | AK8: =AE8/$H8 -> 0 | AL8: =AF8/$H8 -> 0 | AM8: =AG8/$H8 -> 1
B9: Module6 | C9: =_xlfn.CONCAT($B9,"!B3:B100") -> Module6!B3:B100 | D9: =_xlfn.CONCAT($B9,"!N3:N100") -> Module6!N3:N100 | E9: =COUNTA(INDIRECT(C9)) -> 20 | F9: =COUNTIF(INDIRECT($D9),F$3) -> 0 | G9: =COUNTIF(INDIRECT($D9),G$3) -> 0 | H9: =COUNTIF(INDIRECT($D9),H$3) -> 20 | I9: =COUNTIF(INDIRECT($D9),I$3) -> 0 | J9: =COUNTIF(INDIRECT($D9),J$3) -> 0 | K9: =E9-SUM(F9:J9) -> 0 | M9: =_xlfn.CONCAT($B9,"!I3:I100") -> Module6!I3:I100 | N9: =COUNTIF(INDIRECT($M9),N$3) -> 0 | O9: =COUNTIF(INDIRECT($M9),O$3) -> 0 | P9: =COUNTIF(INDIRECT($M9),P$3) -> 0 | Q9: =COUNTIF(INDIRECT($M9),Q$3) -> 0 | T9: =(E9-SUM(N9:Q9)) -> 20 | V9: =N9/$E9 -> 0 | W9: =O9/$E9 -> 0 | X9: =P9/$E9 -> 0 | Y9: =Q9/$E9 -> 0 | Z9: =T9/$E9 -> 1 | AB9: =_xlfn.CONCAT($B9,"!p3:p100") -> Module6!p3:p100 | AC9: =COUNTIF(INDIRECT($AB9),AC$3) -> 0 | AD9: =COUNTIF(INDIRECT($AB9),AD$3) -> 0 | AE9: =COUNTIF(INDIRECT($AB9),AE$3) -> 0 | AF9: =COUNTIF(INDIRECT($AB9),AF$3) -> 0 | AG9: =(H9-SUM(AC9:AF9)) -> 20 | AI9: =AC9/$H9 -> 0 | AJ9: =AD9/$H9 -> 0 | AK9: =AE9/$H9 -> 0 | AL9: =AF9/$H9 -> 0 | AM9: =AG9/$H9 -> 1
B10: Module7 | C10: =_xlfn.CONCAT($B10,"!B3:B100") -> Module7!B3:B100 | D10: =_xlfn.CONCAT($B10,"!N3:N100") -> Module7!N3:N100 | E10: =COUNTA(INDIRECT(C10)) -> 9 | F10: =COUNTIF(INDIRECT($D10),F$3) -> 2 | G10: =COUNTIF(INDIRECT($D10),G$3) -> 0 | H10: =COUNTIF(INDIRECT($D10),H$3) -> 5 | I10: =COUNTIF(INDIRECT($D10),I$3) -> 0 | J10: =COUNTIF(INDIRECT($D10),J$3) -> 0 | K10: =E10-SUM(F10:J10) -> 2 | M10: =_xlfn.CONCAT($B10,"!I3:I100") -> Module7!I3:I100 | N10: =COUNTIF(INDIRECT($M10),N$3) -> 0 | O10: =COUNTIF(INDIRECT($M10),O$3) -> 0 | P10: =COUNTIF(INDIRECT($M10),P$3) -> 0 | Q10: =COUNTIF(INDIRECT($M10),Q$3) -> 0 | T10: =(E10-SUM(N10:Q10)) -> 9 | V10: =N10/$E10 -> 0 | W10: =O10/$E10 -> 0 | X10: =P10/$E10 -> 0 | Y10: =Q10/$E10 -> 0 | Z10: =T10/$E10 -> 1 | AB10: =_xlfn.CONCAT($B10,"!p3:p100") -> Module7!p3:p100 | AC10: =COUNTIF(INDIRECT($AB10),AC$3) -> 0 | AD10: =COUNTIF(INDIRECT($AB10),AD$3) -> 0 | AE10: =COUNTIF(INDIRECT($AB10),AE$3) -> 0 | AF10: =COUNTIF(INDIRECT($AB10),AF$3) -> 0 | AG10: =(H10-SUM(AC10:AF10)) -> 5 | AI10: =AC10/$H10 -> 0 | AJ10: =AD10/$H10 -> 0 | AK10: =AE10/$H10 -> 0 | AL10: =AF10/$H10 -> 0 | AM10: =AG10/$H10 -> 1
B11: Module8 | C11: =_xlfn.CONCAT($B11,"!B3:B100") -> Module8!B3:B100 | D11: =_xlfn.CONCAT($B11,"!N3:N100") -> Module8!N3:N100 | E11: =COUNTA(INDIRECT(C11)) -> 26 | F11: =COUNTIF(INDIRECT($D11),F$3) -> 0 | G11: =COUNTIF(INDIRECT($D11),G$3) -> 1 | H11: =COUNTIF(INDIRECT($D11),H$3) -> 24 | I11: =COUNTIF(INDIRECT($D11),I$3) -> 1 | J11: =COUNTIF(INDIRECT($D11),J$3) -> 0 | K11: =E11-SUM(F11:J11) -> 0 | M11: =_xlfn.CONCAT($B11,"!I3:I100") -> Module8!I3:I100 | N11: =COUNTIF(INDIRECT($M11),N$3) -> 0 | O11: =COUNTIF(INDIRECT($M11),O$3) -> 0 | P11: =COUNTIF(INDIRECT($M11),P$3) -> 0 | Q11: =COUNTIF(INDIRECT($M11),Q$3) -> 0 | T11: =(E11-SUM(N11:Q11)) -> 26 | V11: =N11/$E11 -> 0 | W11: =O11/$E11 -> 0 | X11: =P11/$E11 -> 0 | Y11: =Q11/$E11 -> 0 | Z11: =T11/$E11 -> 1 | AB11: =_xlfn.CONCAT($B11,"!p3:p100") -> Module8!p3:p100 | AC11: =COUNTIF(INDIRECT($AB11),AC$3) -> 0 | AD11: =COUNTIF(INDIRECT($AB11),AD$3) -> 0 | AE11: =COUNTIF(INDIRECT($AB11),AE$3) -> 0 | AF11: =COUNTIF(INDIRECT($AB11),AF$3) -> 0 | AG11: =(H11-SUM(AC11:AF11)) -> 24 | AI11: =AC11/$H11 -> 0 | AJ11: =AD11/$H11 -> 0 | AK11: =AE11/$H11 -> 0 | AL11: =AF11/$H11 -> 0 | AM11: =AG11/$H11 -> 1
B12: TOTAL | E12: =SUM(E4:E11) -> 155 | F12: =SUM(F4:F11) -> 2 | G12: =SUM(G4:G11) -> 3 | H12: =SUM(H4:H11) -> 126 | I12: =SUM(I4:I11) -> 17 | J12: =SUM(J4:J11) -> 3 | K12: =E12-SUM(F12:J12) -> 4 | N12: =SUM(N4:N11) -> 0 | O12: =SUM(O4:O11) -> 0 | P12: =SUM(P4:P11) -> 0 | Q12: =SUM(Q4:Q11) -> 0 | T12: =(E12-SUM(N12:Q12)) -> 155 | V12: =N12/$E12 -> 0 | W12: =O12/$E12 -> 0 | X12: =P12/$E12 -> 0 | Y12: =Q12/$E12 -> 0 | Z12: =T12/$E12 -> 1 | AC12: =SUM(AC4:AC11) -> 0 | AD12: =SUM(AD4:AD11) -> 0 | AE12: =SUM(AE4:AE11) -> 0 | AF12: =SUM(AF4:AF11) -> 0 | AG12: =(H12-SUM(AC12:AF12)) -> 126 | AI12: =AC12/$H12 -> 0 | AJ12: =AD12/$H12 -> 0 | AK12: =AE12/$H12 -> 0 | AL12: =AF12/$H12 -> 0 | AM12: =AG12/$H12 -> 1
F15: DATASET STATUS | V15: DATASET STATUS
B16: Lead | E16: TOTAL Charts | F16: {=TRANSPOSE(Validation!J2:J7)} -> Pending | G16: In process | H16: Review pending | I16: Needs fixing | J16: Ready | K16: Deleted | V16: {=TRANSPOSE(Validation!I2:I5)} -> Pending | W16: In process | X16: Not supported by pipeline | Y16: Ready
B17: Gabriela | E17: =COUNTIF(ChartsM1[Lead],TRACKER!B17)+COUNTIF(ChartsM2[Lead],TRACKER!B17)++COUNTIF(ChartsM3[Lead],TRACKER!B17)+COUNTIF(ChartsM4[Lead],TRACKER!B17)+COUNTIF(ChartsM5[Lead],TRACKER!B17)+COUNTIF(ChartsM6[Lead],TRACKER!B17)+COUNTIF(ChartsM7[Lead],TRACKER!B17)+COUNTIF(ChartsM8[Lead],TRACKER!B17) -> 35 | F17: =(COUNTIFS(ChartsM1[Lead],TRACKER!$B17,ChartsM1[Dataset Status],TRACKER!$F$16) +COUNTIFS(ChartsM2[Lead],TRACKER!$B17,ChartsM2[Dataset Status],TRACKER!$F$16) +COUNTIFS(ChartsM3[Lead],TRACKER!$B17,ChartsM3[Dataset Status],TRACKER!$F$16) +COUNTIFS(ChartsM4[Lead],TRACKER!$B17,ChartsM4[Dataset Status],TRACKER!$F$16) +COUNTIFS(ChartsM5[Lead],TRACKER!$B17,ChartsM5[Dataset Status],TRACKER!$F$16) +COUNTIFS(ChartsM6[Lead],TRACKER!$B17,ChartsM6[Dataset Status],TRACKER!$F$16) +COUNTIFS(ChartsM7[Lead],TRACKER!$B17,ChartsM7[Dataset Status],TRACKER!$F$16) +COUNTIFS(ChartsM8[Lead],TRACKER!$B17,ChartsM8[Dataset Status],TRACKER!$F$16)) -> 4 | G17: =(COUNTIFS(ChartsM1[Lead],TRACKER!$B17,ChartsM1[Dataset Status],TRACKER!$G$16) +COUNTIFS(ChartsM2[Lead],TRACKER!$B17,ChartsM2[Dataset Status],TRACKER!$G$16) +COUNTIFS(ChartsM3[Lead],TRACKER!$B17,ChartsM3[Dataset Status],TRACKER!$G$16) +COUNTIFS(ChartsM4[Lead],TRACKER!$B17,ChartsM4[Dataset Status],TRACKER!$G$16) +COUNTIFS(ChartsM5[Lead],TRACKER!$B17,ChartsM5[Dataset Status],TRACKER!$G$16) +COUNTIFS(ChartsM6[Lead],TRACKER!$B17,ChartsM6[Dataset Status],TRACKER!$G$16) +COUNTIFS(ChartsM7[Lead],TRACKER!$B17,ChartsM7[Dataset Status],TRACKER!$G$16) +COUNTIFS(ChartsM8[Lead],TRACKER!$B17,ChartsM8[Dataset Status],TRACKER!$G$16)) -> 0 | H17: =(COUNTIFS(ChartsM1[Lead],TRACKER!$B17,ChartsM1[Dataset Status],TRACKER!$H$16) +COUNTIFS(ChartsM2[Lead],TRACKER!$B17,ChartsM2[Dataset Status],TRACKER!$H$16) +COUNTIFS(ChartsM3[Lead],TRACKER!$B17,ChartsM3[Dataset Status],TRACKER!$H$16) +COUNTIFS(ChartsM4[Lead],TRACKER!$B17,ChartsM4[Dataset Status],TRACKER!$H$16) +COUNTIFS(ChartsM5[Lead],TRACKER!$B17,ChartsM5[Dataset Status],TRACKER!$H$16) +COUNTIFS(ChartsM6[Lead],TRACKER!$B17,ChartsM6[Dataset Status],TRACKER!$H$16) +COUNTIFS(ChartsM7[Lead],TRACKER!$B17,ChartsM7[Dataset Status],TRACKER!$H$16) +COUNTIFS(ChartsM8[Lead],TRACKER!$B17,ChartsM8[Dataset Status],TRACKER!$H$16)) -> 3 | I17: =(COUNTIFS(ChartsM1[Lead],TRACKER!$B17,ChartsM1[Dataset Status],TRACKER!$I$16) +COUNTIFS(ChartsM2[Lead],TRACKER!$B17,ChartsM2[Dataset Status],TRACKER!$I$16) +COUNTIFS(ChartsM3[Lead],TRACKER!$B17,ChartsM3[Dataset Status],TRACKER!$I$16) +COUNTIFS(ChartsM4[Lead],TRACKER!$B17,ChartsM4[Dataset Status],TRACKER!$I$16) +COUNTIFS(ChartsM5[Lead],TRACKER!$B17,ChartsM5[Dataset Status],TRACKER!$I$16) +COUNTIFS(ChartsM6[Lead],TRACKER!$B17,ChartsM6[Dataset Status],TRACKER!$I$16) +COUNTIFS(ChartsM7[Lead],TRACKER!$B17,ChartsM7[Dataset Status],TRACKER!$I$16) +COUNTIFS(ChartsM8[Lead],TRACKER!$B17,ChartsM8[Dataset Status],TRACKER!$I$16)) -> 0 | J17: =(COUNTIFS(ChartsM1[Lead],TRACKER!$B17,ChartsM1[Dataset Status],TRACKER!$J$16) +COUNTIFS(ChartsM2[Lead],TRACKER!$B17,ChartsM2[Dataset Status],TRACKER!$J$16) +COUNTIFS(ChartsM3[Lead],TRACKER!$B17,ChartsM3[Dataset Status],TRACKER!$J$16) +COUNTIFS(ChartsM4[Lead],TRACKER!$B17,ChartsM4[Dataset Status],TRACKER!$J$16) +COUNTIFS(ChartsM5[Lead],TRACKER!$B17,ChartsM5[Dataset Status],TRACKER!$J$16) +COUNTIFS(ChartsM6[Lead],TRACKER!$B17,ChartsM6[Dataset Status],TRACKER!$J$16) +COUNTIFS(ChartsM7[Lead],TRACKER!$B17,ChartsM7[Dataset Status],TRACKER!$J$16) +COUNTIFS(ChartsM8[Lead],TRACKER!$B17,ChartsM8[Dataset Status],TRACKER!$J$16)) -> 25 | K17: =(COUNTIFS(ChartsM1[Lead],TRACKER!$B17,ChartsM1[Dataset Status],TRACKER!$K$16) +COUNTIFS(ChartsM2[Lead],TRACKER!$B17,ChartsM2[Dataset Status],TRACKER!$K$16) +COUNTIFS(ChartsM3[Lead],TRACKER!$B17,ChartsM3[Dataset Status],TRACKER!$K$16) +COUNTIFS(ChartsM4[Lead],TRACKER!$B17,ChartsM4[Dataset Status],TRACKER!$K$16) +COUNTIFS(ChartsM5[Lead],TRACKER!$B17,ChartsM5[Dataset Status],TRACKER!$K$16) +COUNTIFS(ChartsM6[Lead],TRACKER!$B17,ChartsM6[Dataset Status],TRACKER!$K$16) +COUNTIFS(ChartsM7[Lead],TRACKER!$B17,ChartsM7[Dataset Status],TRACKER!$K$16) +COUNTIFS(ChartsM8[Lead],TRACKER!$B17,ChartsM8[Dataset Status],TRACKER!$K$16)) -> 1 | V17: =F17/$E17 -> 0.11428571 | W17: =G17/$E17 -> 0 | X17: =I17/$E17 -> 0
B18: Zhong | E18: =COUNTIF(ChartsM1[Lead],TRACKER!B18)+COUNTIF(ChartsM2[Lead],TRACKER!B18)++COUNTIF(ChartsM3[Lead],TRACKER!B18)+COUNTIF(ChartsM4[Lead],TRACKER!B18)+COUNTIF(ChartsM5[Lead],TRACKER!B18)+COUNTIF(ChartsM6[Lead],TRACKER!B18)+COUNTIF(ChartsM7[Lead],TRACKER!B18)+COUNTIF(ChartsM8[Lead],TRACKER!B18) -> 32 | F18: =(COUNTIFS(ChartsM1[Lead],TRACKER!$B18,ChartsM1[Dataset Status],TRACKER!$F$16) +COUNTIFS(ChartsM2[Lead],TRACKER!$B18,ChartsM2[Dataset Status],TRACKER!$F$16) +COUNTIFS(ChartsM3[Lead],TRACKER!$B18,ChartsM3[Dataset Status],TRACKER!$F$16) +COUNTIFS(ChartsM4[Lead],TRACKER!$B18,ChartsM4[Dataset Status],TRACKER!$F$16) +COUNTIFS(ChartsM5[Lead],TRACKER!$B18,ChartsM5[Dataset Status],TRACKER!$F$16) +COUNTIFS(ChartsM6[Lead],TRACKER!$B18,ChartsM6[Dataset Status],TRACKER!$F$16) +COUNTIFS(ChartsM7[Lead],TRACKER!$B18,ChartsM7[Dataset Status],TRACKER!$F$16) +COUNTIFS(ChartsM8[Lead],TRACKER!$B18,ChartsM8[Dataset Status],TRACKER!$F$16)) -> 4 | G18: =(COUNTIFS(ChartsM1[Lead],TRACKER!$B18,ChartsM1[Dataset Status],TRACKER!$G$16) +COUNTIFS(ChartsM2[Lead],TRACKER!$B18,ChartsM2[Dataset Status],TRACKER!$G$16) +COUNTIFS(ChartsM3[Lead],TRACKER!$B18,ChartsM3[Dataset Status],TRACKER!$G$16) +COUNTIFS(ChartsM4[Lead],TRACKER!$B18,ChartsM4[Dataset Status],TRACKER!$G$16) +COUNTIFS(ChartsM5[Lead],TRACKER!$B18,ChartsM5[Dataset Status],TRACKER!$G$16) +COUNTIFS(ChartsM6[Lead],TRACKER!$B18,ChartsM6[Dataset Status],TRACKER!$G$16) +COUNTIFS(ChartsM7[Lead],TRACKER!$B18,ChartsM7[Dataset Status],TRACKER!$G$16) +COUNTIFS(ChartsM8[Lead],TRACKER!$B18,ChartsM8[Dataset Status],TRACKER!$G$16)) -> 0 | H18: =(COUNTIFS(ChartsM1[Lead],TRACKER!$B18,ChartsM1[Dataset Status],TRACKER!$H$16) +COUNTIFS(ChartsM2[Lead],TRACKER!$B18,ChartsM2[Dataset Status],TRACKER!$H$16) +COUNTIFS(ChartsM3[Lead],TRACKER!$B18,ChartsM3[Dataset Status],TRACKER!$H$16) +COUNTIFS(ChartsM4[Lead],TRACKER!$B18,ChartsM4[Dataset Status],TRACKER!$H$16) +COUNTIFS(ChartsM5[Lead],TRACKER!$B18,ChartsM5[Dataset Status],TRACKER!$H$16) +COUNTIFS(ChartsM6[Lead],TRACKER!$B18,ChartsM6[Dataset Status],TRACKER!$H$16) +COUNTIFS(ChartsM7[Lead],TRACKER!$B18,ChartsM7[Dataset Status],TRACKER!$H$16) +COUNTIFS(ChartsM8[Lead],TRACKER!$B18,ChartsM8[Dataset Status],TRACKER!$H$16)) -> 0 | I18: =(COUNTIFS(ChartsM1[Lead],TRACKER!$B18,ChartsM1[Dataset Status],TRACKER!$I$16) +COUNTIFS(ChartsM2[Lead],TRACKER!$B18,ChartsM2[Dataset Status],TRACKER!$I$16) +COUNTIFS(ChartsM3[Lead],TRACKER!$B18,ChartsM3[Dataset Status],TRACKER!$I$16) +COUNTIFS(ChartsM4[Lead],TRACKER!$B18,ChartsM4[Dataset Status],TRACKER!$I$16) +COUNTIFS(ChartsM5[Lead],TRACKER!$B18,ChartsM5[Dataset Status],TRACKER!$I$16) +COUNTIFS(ChartsM6[Lead],TRACKER!$B18,ChartsM6[Dataset Status],TRACKER!$I$16) +COUNTIFS(ChartsM7[Lead],TRACKER!$B18,ChartsM7[Dataset Status],TRACKER!$I$16) +COUNTIFS(ChartsM8[Lead],TRACKER!$B18,ChartsM8[Dataset Status],TRACKER!$I$16)) -> 0 | J18: =(COUNTIFS(ChartsM1[Lead],TRACKER!$B18,ChartsM1[Dataset Status],TRACKER!$J$16) +COUNTIFS(ChartsM2[Lead],TRACKER!$B18,ChartsM2[Dataset Status],TRACKER!$J$16) +COUNTIFS(ChartsM3[Lead],TRACKER!$B18,ChartsM3[Dataset Status],TRACKER!$J$16) +COUNTIFS(ChartsM4[Lead],TRACKER!$B18,ChartsM4[Dataset Status],TRACKER!$J$16) +COUNTIFS(ChartsM5[Lead],TRACKER!$B18,ChartsM5[Dataset Status],TRACKER!$J$16) +COUNTIFS(ChartsM6[Lead],TRACKER!$B18,ChartsM6[Dataset Status],TRACKER!$J$16) +COUNTIFS(ChartsM7[Lead],TRACKER!$B18,ChartsM7[Dataset Status],TRACKER!$J$16) +COUNTIFS(ChartsM8[Lead],TRACKER!$B18,ChartsM8[Dataset Status],TRACKER!$J$16)) -> 24 | K18: =(COUNTIFS(ChartsM1[Lead],TRACKER!$B18,ChartsM1[Dataset Status],TRACKER!$K$16) +COUNTIFS(ChartsM2[Lead],TRACKER!$B18,ChartsM2[Dataset Status],TRACKER!$K$16) +COUNTIFS(ChartsM3[Lead],TRACKER!$B18,ChartsM3[Dataset Status],TRACKER!$K$16) +COUNTIFS(ChartsM4[Lead],TRACKER!$B18,ChartsM4[Dataset Status],TRACKER!$K$16) +COUNTIFS(ChartsM5[Lead],TRACKER!$B18,ChartsM5[Dataset Status],TRACKER!$K$16) +COUNTIFS(ChartsM6[Lead],TRACKER!$B18,ChartsM6[Dataset Status],TRACKER!$K$16) +COUNTIFS(ChartsM7[Lead],TRACKER!$B18,ChartsM7[Dataset Status],TRACKER!$K$16) +COUNTIFS(ChartsM8[Lead],TRACKER!$B18,ChartsM8[Dataset Status],TRACKER!$K$16)) -> 1 | V18: =F18/$E18 -> 0.125 | W18: =G18/$E18 -> 0 | X18: =I18/$E18 -> 0
B19: Divya | E19: =COUNTIF(ChartsM1[Lead],TRACKER!B19)+COUNTIF(ChartsM2[Lead],TRACKER!B19)++COUNTIF(ChartsM3[Lead],TRACKER!B19)+COUNTIF(ChartsM4[Lead],TRACKER!B19)+COUNTIF(ChartsM5[Lead],TRACKER!B19)+COUNTIF(ChartsM6[Lead],TRACKER!B19)+COUNTIF(ChartsM7[Lead],TRACKER!B19)+COUNTIF(ChartsM8[Lead],TRACKER!B19) -> 29 | F19: =(COUNTIFS(ChartsM1[Lead],TRACKER!$B19,ChartsM1[Dataset Status],TRACKER!$F$16) +COUNTIFS(ChartsM2[Lead],TRACKER!$B19,ChartsM2[Dataset Status],TRACKER!$F$16) +COUNTIFS(ChartsM3[Lead],TRACKER!$B19,ChartsM3[Dataset Status],TRACKER!$F$16) +COUNTIFS(ChartsM4[Lead],TRACKER!$B19,ChartsM4[Dataset Status],TRACKER!$F$16) +COUNTIFS(ChartsM5[Lead],TRACKER!$B19,ChartsM5[Dataset Status],TRACKER!$F$16) +COUNTIFS(ChartsM6[Lead],TRACKER!$B19,ChartsM6[Dataset Status],TRACKER!$F$16) +COUNTIFS(ChartsM7[Lead],TRACKER!$B19,ChartsM7[Dataset Status],TRACKER!$F$16) +COUNTIFS(ChartsM8[Lead],TRACKER!$B19,ChartsM8[Dataset Status],TRACKER!$F$16)) -> 2 | G19: =(COUNTIFS(ChartsM1[Lead],TRACKER!$B19,ChartsM1[Dataset Status],TRACKER!$G$16) +COUNTIFS(ChartsM2[Lead],TRACKER!$B19,ChartsM2[Dataset Status],TRACKER!$G$16) +COUNTIFS(ChartsM3[Lead],TRACKER!$B19,ChartsM3[Dataset Status],TRACKER!$G$16) +COUNTIFS(ChartsM4[Lead],TRACKER!$B19,ChartsM4[Dataset Status],TRACKER!$G$16) +COUNTIFS(ChartsM5[Lead],TRACKER!$B19,ChartsM5[Dataset Status],TRACKER!$G$16) +COUNTIFS(ChartsM6[Lead],TRACKER!$B19,ChartsM6[Dataset Status],TRACKER!$G$16) +COUNTIFS(ChartsM7[Lead],TRACKER!$B19,ChartsM7[Dataset Status],TRACKER!$G$16) +COUNTIFS(ChartsM8[Lead],TRACKER!$B19,ChartsM8[Dataset Status],TRACKER!$G$16)) -> 4 | H19: =(COUNTIFS(ChartsM1[Lead],TRACKER!$B19,ChartsM1[Dataset Status],TRACKER!$H$16) +COUNTIFS(ChartsM2[Lead],TRACKER!$B19,ChartsM2[Dataset Status],TRACKER!$H$16) +COUNTIFS(ChartsM3[Lead],TRACKER!$B19,ChartsM3[Dataset Status],TRACKER!$H$16) +COUNTIFS(ChartsM4[Lead],TRACKER!$B19,ChartsM4[Dataset Status],TRACKER!$H$16) +COUNTIFS(ChartsM5[Lead],TRACKER!$B19,ChartsM5[Dataset Status],TRACKER!$H$16) +COUNTIFS(ChartsM6[Lead],TRACKER!$B19,ChartsM6[Dataset Status],TRACKER!$H$16) +COUNTIFS(ChartsM7[Lead],TRACKER!$B19,ChartsM7[Dataset Status],TRACKER!$H$16) +COUNTIFS(ChartsM8[Lead],TRACKER!$B19,ChartsM8[Dataset Status],TRACKER!$H$16)) -> 2 | I19: =(COUNTIFS(ChartsM1[Lead],TRACKER!$B19,ChartsM1[Dataset Status],TRACKER!$I$16) +COUNTIFS(ChartsM2[Lead],TRACKER!$B19,ChartsM2[Dataset Status],TRACKER!$I$16) +COUNTIFS(ChartsM3[Lead],TRACKER!$B19,ChartsM3[Dataset Status],TRACKER!$I$16) +COUNTIFS(ChartsM4[Lead],TRACKER!$B19,ChartsM4[Dataset Status],TRACKER!$I$16) +COUNTIFS(ChartsM5[Lead],TRACKER!$B19,ChartsM5[Dataset Status],TRACKER!$I$16) +COUNTIFS(ChartsM6[Lead],TRACKER!$B19,ChartsM6[Dataset Status],TRACKER!$I$16) +COUNTIFS(ChartsM7[Lead],TRACKER!$B19,ChartsM7[Dataset Status],TRACKER!$I$16) +COUNTIFS(ChartsM8[Lead],TRACKER!$B19,ChartsM8[Dataset Status],TRACKER!$I$16)) -> 0 | J19: =(COUNTIFS(ChartsM1[Lead],TRACKER!$B19,ChartsM1[Dataset Status],TRACKER!$J$16) +COUNTIFS(ChartsM2[Lead],TRACKER!$B19,ChartsM2[Dataset Status],TRACKER!$J$16) +COUNTIFS(ChartsM3[Lead],TRACKER!$B19,ChartsM3[Dataset Status],TRACKER!$J$16) +COUNTIFS(ChartsM4[Lead],TRACKER!$B19,ChartsM4[Dataset Status],TRACKER!$J$16) +COUNTIFS(ChartsM5[Lead],TRACKER!$B19,ChartsM5[Dataset Status],TRACKER!$J$16) +COUNTIFS(ChartsM6[Lead],TRACKER!$B19,ChartsM6[Dataset Status],TRACKER!$J$16) +COUNTIFS(ChartsM7[Lead],TRACKER!$B19,ChartsM7[Dataset Status],TRACKER!$J$16) +COUNTIFS(ChartsM8[Lead],TRACKER!$B19,ChartsM8[Dataset Status],TRACKER!$J$16)) -> 20 | K19: =(COUNTIFS(ChartsM1[Lead],TRACKER!$B19,ChartsM1[Dataset Status],TRACKER!$K$16) +COUNTIFS(ChartsM2[Lead],TRACKER!$B19,ChartsM2[Dataset Status],TRACKER!$K$16) +COUNTIFS(ChartsM3[Lead],TRACKER!$B19,ChartsM3[Dataset Status],TRACKER!$K$16) +COUNTIFS(ChartsM4[Lead],TRACKER!$B19,ChartsM4[Dataset Status],TRACKER!$K$16) +COUNTIFS(ChartsM5[Lead],TRACKER!$B19,ChartsM5[Dataset Status],TRACKER!$K$16) +COUNTIFS(ChartsM6[Lead],TRACKER!$B19,ChartsM6[Dataset Status],TRACKER!$K$16) +COUNTIFS(ChartsM7[Lead],TRACKER!$B19,ChartsM7[Dataset Status],TRACKER!$K$16) +COUNTIFS(ChartsM8[Lead],TRACKER!$B19,ChartsM8[Dataset Status],TRACKER!$K$16)) -> 1 | V19: =F19/$E19 -> 0.068965517 | W19: =G19/$E19 -> 0.13793103 | X19: =I19/$E19 -> 0
B20: Danae | E20: =COUNTIF(ChartsM1[Lead],TRACKER!B20)+COUNTIF(ChartsM2[Lead],TRACKER!B20)++COUNTIF(ChartsM3[Lead],TRACKER!B20)+COUNTIF(ChartsM4[Lead],TRACKER!B20)+COUNTIF(ChartsM5[Lead],TRACKER!B20)+COUNTIF(ChartsM6[Lead],TRACKER!B20)+COUNTIF(ChartsM7[Lead],TRACKER!B20)+COUNTIF(ChartsM8[Lead],TRACKER!B20) -> 23 | F20: =(COUNTIFS(ChartsM1[Lead],TRACKER!$B20,ChartsM1[Dataset Status],TRACKER!$F$16) +COUNTIFS(ChartsM2[Lead],TRACKER!$B20,ChartsM2[Dataset Status],TRACKER!$F$16) +COUNTIFS(ChartsM3[Lead],TRACKER!$B20,ChartsM3[Dataset Status],TRACKER!$F$16) +COUNTIFS(ChartsM4[Lead],TRACKER!$B20,ChartsM4[Dataset Status],TRACKER!$F$16) +COUNTIFS(ChartsM5[Lead],TRACKER!$B20,ChartsM5[Dataset Status],TRACKER!$F$16) +COUNTIFS(ChartsM6[Lead],TRACKER!$B20,ChartsM6[Dataset Status],TRACKER!$F$16) +COUNTIFS(ChartsM7[Lead],TRACKER!$B20,ChartsM7[Dataset Status],TRACKER!$F$16) +COUNTIFS(ChartsM8[Lead],TRACKER!$B20,ChartsM8[Dataset Status],TRACKER!$F$16)) -> 0 | G20: =(COUNTIFS(ChartsM1[Lead],TRACKER!$B20,ChartsM1[Dataset Status],TRACKER!$G$16) +COUNTIFS(ChartsM2[Lead],TRACKER!$B20,ChartsM2[Dataset Status],TRACKER!$G$16) +COUNTIFS(ChartsM3[Lead],TRACKER!$B20,ChartsM3[Dataset Status],TRACKER!$G$16) +COUNTIFS(ChartsM4[Lead],TRACKER!$B20,ChartsM4[Dataset Status],TRACKER!$G$16) +COUNTIFS(ChartsM5[Lead],TRACKER!$B20,ChartsM5[Dataset Status],TRACKER!$G$16) +COUNTIFS(ChartsM6[Lead],TRACKER!$B20,ChartsM6[Dataset Status],TRACKER!$G$16) +COUNTIFS(ChartsM7[Lead],TRACKER!$B20,ChartsM7[Dataset Status],TRACKER!$G$16) +COUNTIFS(ChartsM8[Lead],TRACKER!$B20,ChartsM8[Dataset Status],TRACKER!$G$16)) -> 0 | H20: =(COUNTIFS(ChartsM1[Lead],TRACKER!$B20,ChartsM1[Dataset Status],TRACKER!$H$16) +COUNTIFS(ChartsM2[Lead],TRACKER!$B20,ChartsM2[Dataset Status],TRACKER!$H$16) +COUNTIFS(ChartsM3[Lead],TRACKER!$B20,ChartsM3[Dataset Status],TRACKER!$H$16) +COUNTIFS(ChartsM4[Lead],TRACKER!$B20,ChartsM4[Dataset Status],TRACKER!$H$16) +COUNTIFS(ChartsM5[Lead],TRACKER!$B20,ChartsM5[Dataset Status],TRACKER!$H$16) +COUNTIFS(ChartsM6[Lead],TRACKER!$B20,ChartsM6[Dataset Status],TRACKER!$H$16) +COUNTIFS(ChartsM7[Lead],TRACKER!$B20,ChartsM7[Dataset Status],TRACKER!$H$16) +COUNTIFS(ChartsM8[Lead],TRACKER!$B20,ChartsM8[Dataset Status],TRACKER!$H$16)) -> 11 | I20: =(COUNTIFS(ChartsM1[Lead],TRACKER!$B20,ChartsM1[Dataset Status],TRACKER!$I$16) +COUNTIFS(ChartsM2[Lead],TRACKER!$B20,ChartsM2[Dataset Status],TRACKER!$I$16) +COUNTIFS(ChartsM3[Lead],TRACKER!$B20,ChartsM3[Dataset Status],TRACKER!$I$16) +COUNTIFS(ChartsM4[Lead],TRACKER!$B20,ChartsM4[Dataset Status],TRACKER!$I$16) +COUNTIFS(ChartsM5[Lead],TRACKER!$B20,ChartsM5[Dataset Status],TRACKER!$I$16) +COUNTIFS(ChartsM6[Lead],TRACKER!$B20,ChartsM6[Dataset Status],TRACKER!$I$16) +COUNTIFS(ChartsM7[Lead],TRACKER!$B20,ChartsM7[Dataset Status],TRACKER!$I$16) +COUNTIFS(ChartsM8[Lead],TRACKER!$B20,ChartsM8[Dataset Status],TRACKER!$I$16)) -> 0 | J20: =(COUNTIFS(ChartsM1[Lead],TRACKER!$B20,ChartsM1[Dataset Status],TRACKER!$J$16) +COUNTIFS(ChartsM2[Lead],TRACKER!$B20,ChartsM2[Dataset Status],TRACKER!$J$16) +COUNTIFS(ChartsM3[Lead],TRACKER!$B20,ChartsM3[Dataset Status],TRACKER!$J$16) +COUNTIFS(ChartsM4[Lead],TRACKER!$B20,ChartsM4[Dataset Status],TRACKER!$J$16) +COUNTIFS(ChartsM5[Lead],TRACKER!$B20,ChartsM5[Dataset Status],TRACKER!$J$16) +COUNTIFS(ChartsM6[Lead],TRACKER!$B20,ChartsM6[Dataset Status],TRACKER!$J$16) +COUNTIFS(ChartsM7[Lead],TRACKER!$B20,ChartsM7[Dataset Status],TRACKER!$J$16) +COUNTIFS(ChartsM8[Lead],TRACKER!$B20,ChartsM8[Dataset Status],TRACKER!$J$16)) -> 12 | K20: =(COUNTIFS(ChartsM1[Lead],TRACKER!$B20,ChartsM1[Dataset Status],TRACKER!$K$16) +COUNTIFS(ChartsM2[Lead],TRACKER!$B20,ChartsM2[Dataset Status],TRACKER!$K$16) +COUNTIFS(ChartsM3[Lead],TRACKER!$B20,ChartsM3[Dataset Status],TRACKER!$K$16) +COUNTIFS(ChartsM4[Lead],TRACKER!$B20,ChartsM4[Dataset Status],TRACKER!$K$16) +COUNTIFS(ChartsM5[Lead],TRACKER!$B20,ChartsM5[Dataset Status],TRACKER!$K$16) +COUNTIFS(ChartsM6[Lead],TRACKER!$B20,ChartsM6[Dataset Status],TRACKER!$K$16) +COUNTIFS(ChartsM7[Lead],TRACKER!$B20,ChartsM7[Dataset Status],TRACKER!$K$16) +COUNTIFS(ChartsM8[Lead],TRACKER!$B20,ChartsM8[Dataset Status],TRACKER!$K$16)) -> 0 | V20: =F20/$E20 -> 0 | W20: =G20/$E20 -> 0 | X20: =I20/$E20 -> 0
B21: Ahmad | E21: =COUNTIF(ChartsM1[Lead],TRACKER!B21)+COUNTIF(ChartsM2[Lead],TRACKER!B21)++COUNTIF(ChartsM3[Lead],TRACKER!B21)+COUNTIF(ChartsM4[Lead],TRACKER!B21)+COUNTIF(ChartsM5[Lead],TRACKER!B21)+COUNTIF(ChartsM6[Lead],TRACKER!B21)+COUNTIF(ChartsM7[Lead],TRACKER!B21)+COUNTIF(ChartsM8[Lead],TRACKER!B21) -> 5 | F21: =(COUNTIFS(ChartsM1[Lead],TRACKER!$B21,ChartsM1[Dataset Status],TRACKER!$F$16) +COUNTIFS(ChartsM2[Lead],TRACKER!$B21,ChartsM2[Dataset Status],TRACKER!$F$16) +COUNTIFS(ChartsM3[Lead],TRACKER!$B21,ChartsM3[Dataset Status],TRACKER!$F$16) +COUNTIFS(ChartsM4[Lead],TRACKER!$B21,ChartsM4[Dataset Status],TRACKER!$F$16) +COUNTIFS(ChartsM5[Lead],TRACKER!$B21,ChartsM5[Dataset Status],TRACKER!$F$16) +COUNTIFS(ChartsM6[Lead],TRACKER!$B21,ChartsM6[Dataset Status],TRACKER!$F$16) +COUNTIFS(ChartsM7[Lead],TRACKER!$B21,ChartsM7[Dataset Status],TRACKER!$F$16) +COUNTIFS(ChartsM8[Lead],TRACKER!$B21,ChartsM8[Dataset Status],TRACKER!$F$16)) -> 4 | G21: =(COUNTIFS(ChartsM1[Lead],TRACKER!$B21,ChartsM1[Dataset Status],TRACKER!$G$16) +COUNTIFS(ChartsM2[Lead],TRACKER!$B21,ChartsM2[Dataset Status],TRACKER!$G$16) +COUNTIFS(ChartsM3[Lead],TRACKER!$B21,ChartsM3[Dataset Status],TRACKER!$G$16) +COUNTIFS(ChartsM4[Lead],TRACKER!$B21,ChartsM4[Dataset Status],TRACKER!$G$16) +COUNTIFS(ChartsM5[Lead],TRACKER!$B21,ChartsM5[Dataset Status],TRACKER!$G$16) +COUNTIFS(ChartsM6[Lead],TRACKER!$B21,ChartsM6[Dataset Status],TRACKER!$G$16) +COUNTIFS(ChartsM7[Lead],TRACKER!$B21,ChartsM7[Dataset Status],TRACKER!$G$16) +COUNTIFS(ChartsM8[Lead],TRACKER!$B21,ChartsM8[Dataset Status],TRACKER!$G$16)) -> 0 | H21: =(COUNTIFS(ChartsM1[Lead],TRACKER!$B21,ChartsM1[Dataset Status],TRACKER!$H$16) +COUNTIFS(ChartsM2[Lead],TRACKER!$B21,ChartsM2[Dataset Status],TRACKER!$H$16) +COUNTIFS(ChartsM3[Lead],TRACKER!$B21,ChartsM3[Dataset Status],TRACKER!$H$16) +COUNTIFS(ChartsM4[Lead],TRACKER!$B21,ChartsM4[Dataset Status],TRACKER!$H$16) +COUNTIFS(ChartsM5[Lead],TRACKER!$B21,ChartsM5[Dataset Status],TRACKER!$H$16) +COUNTIFS(ChartsM6[Lead],TRACKER!$B21,ChartsM6[Dataset Status],TRACKER!$H$16) +COUNTIFS(ChartsM7[Lead],TRACKER!$B21,ChartsM7[Dataset Status],TRACKER!$H$16) +COUNTIFS(ChartsM8[Lead],TRACKER!$B21,ChartsM8[Dataset Status],TRACKER!$H$16)) -> 0 | I21: =(COUNTIFS(ChartsM1[Lead],TRACKER!$B21,ChartsM1[Dataset Status],TRACKER!$I$16) +COUNTIFS(ChartsM2[Lead],TRACKER!$B21,ChartsM2[Dataset Status],TRACKER!$I$16) +COUNTIFS(ChartsM3[Lead],TRACKER!$B21,ChartsM3[Dataset Status],TRACKER!$I$16) +COUNTIFS(ChartsM4[Lead],TRACKER!$B21,ChartsM4[Dataset Status],TRACKER!$I$16) +COUNTIFS(ChartsM5[Lead],TRACKER!$B21,ChartsM5[Dataset Status],TRACKER!$I$16) +COUNTIFS(ChartsM6[Lead],TRACKER!$B21,ChartsM6[Dataset Status],TRACKER!$I$16) +COUNTIFS(ChartsM7[Lead],TRACKER!$B21,ChartsM7[Dataset Status],TRACKER!$I$16) +COUNTIFS(ChartsM8[Lead],TRACKER!$B21,ChartsM8[Dataset Status],TRACKER!$I$16)) -> 0 | J21: =(COUNTIFS(ChartsM1[Lead],TRACKER!$B21,ChartsM1[Dataset Status],TRACKER!$J$16) +COUNTIFS(ChartsM2[Lead],TRACKER!$B21,ChartsM2[Dataset Status],TRACKER!$J$16) +COUNTIFS(ChartsM3[Lead],TRACKER!$B21,ChartsM3[Dataset Status],TRACKER!$J$16) +COUNTIFS(ChartsM4[Lead],TRACKER!$B21,ChartsM4[Dataset Status],TRACKER!$J$16) +COUNTIFS(ChartsM5[Lead],TRACKER!$B21,ChartsM5[Dataset Status],TRACKER!$J$16) +COUNTIFS(ChartsM6[Lead],TRACKER!$B21,ChartsM6[Dataset Status],TRACKER!$J$16) +COUNTIFS(ChartsM7[Lead],TRACKER!$B21,ChartsM7[Dataset Status],TRACKER!$J$16) +COUNTIFS(ChartsM8[Lead],TRACKER!$B21,ChartsM8[Dataset Status],TRACKER!$J$16)) -> 1 | K21: =(COUNTIFS(ChartsM1[Lead],TRACKER!$B21,ChartsM1[Dataset Status],TRACKER!$K$16) +COUNTIFS(ChartsM2[Lead],TRACKER!$B21,ChartsM2[Dataset Status],TRACKER!$K$16) +COUNTIFS(ChartsM3[Lead],TRACKER!$B21,ChartsM3[Dataset Status],TRACKER!$K$16) +COUNTIFS(ChartsM4[Lead],TRACKER!$B21,ChartsM4[Dataset Status],TRACKER!$K$16) +COUNTIFS(ChartsM5[Lead],TRACKER!$B21,ChartsM5[Dataset Status],TRACKER!$K$16) +COUNTIFS(ChartsM6[Lead],TRACKER!$B21,ChartsM6[Dataset Status],TRACKER!$K$16) +COUNTIFS(ChartsM7[Lead],TRACKER!$B21,ChartsM7[Dataset Status],TRACKER!$K$16) +COUNTIFS(ChartsM8[Lead],TRACKER!$B21,ChartsM8[Dataset Status],TRACKER!$K$16)) -> 0
E22: =COUNTIFS(ChartsM1[Lead],"", ChartsM1[Chapter], ">0") +COUNTIFS(ChartsM2[Lead],"", ChartsM2[Chapter], ">0") +COUNTIFS(ChartsM3[Lead],"", ChartsM3[Chapter], ">0") +COUNTIFS(ChartsM4[Lead],"", ChartsM4[Chapter], ">0") +COUNTIFS(ChartsM5[Lead],"", ChartsM5[Chapter], ">0") +COUNTIFS(ChartsM6[Lead],"", ChartsM6[Chapter], ">0") +COUNTIFS(ChartsM7[Lead],"", ChartsM7[Chapter], ">0") +COUNTIFS(ChartsM8[Lead],"", ChartsM8[Chapter], ">0") -> 31 | F22: =(COUNTIFS(ChartsM1[Lead],"",ChartsM1[Dataset Status],TRACKER!$F$16) +COUNTIFS(ChartsM2[Lead],"",ChartsM2[Dataset Status],TRACKER!$F$16) +COUNTIFS(ChartsM3[Lead],"",ChartsM3[Dataset Status],TRACKER!$F$16) +COUNTIFS(ChartsM4[Lead],"",ChartsM4[Dataset Status],TRACKER!$F$16) +COUNTIFS(ChartsM5[Lead],"",ChartsM5[Dataset Status],TRACKER!$F$16) +COUNTIFS(ChartsM6[Lead],"",ChartsM6[Dataset Status],TRACKER!$F$16) +COUNTIFS(ChartsM7[Lead],"",ChartsM7[Dataset Status],TRACKER!$F$16) +COUNTIFS(ChartsM8[Lead],"",ChartsM8[Dataset Status],TRACKER!$F$16)) -> 5 | G22: =(COUNTIFS(ChartsM1[Lead],"",ChartsM1[Dataset Status],TRACKER!$G$16) +COUNTIFS(ChartsM2[Lead],"",ChartsM2[Dataset Status],TRACKER!$G$16) +COUNTIFS(ChartsM3[Lead],"",ChartsM3[Dataset Status],TRACKER!$G$16) +COUNTIFS(ChartsM4[Lead],"",ChartsM4[Dataset Status],TRACKER!$G$16) +COUNTIFS(ChartsM5[Lead],"",ChartsM5[Dataset Status],TRACKER!$G$16) +COUNTIFS(ChartsM6[Lead],"",ChartsM6[Dataset Status],TRACKER!$G$16) +COUNTIFS(ChartsM7[Lead],"",ChartsM7[Dataset Status],TRACKER!$G$16) +COUNTIFS(ChartsM8[Lead],"",ChartsM8[Dataset Status],TRACKER!$G$16)) -> 0 | H22: =(COUNTIFS(ChartsM1[Lead],"",ChartsM1[Dataset Status],TRACKER!$H$16) +COUNTIFS(ChartsM2[Lead],"",ChartsM2[Dataset Status],TRACKER!$H$16) +COUNTIFS(ChartsM3[Lead],"",ChartsM3[Dataset Status],TRACKER!$H$16) +COUNTIFS(ChartsM4[Lead],"",ChartsM4[Dataset Status],TRACKER!$H$16) +COUNTIFS(ChartsM5[Lead],"",ChartsM5[Dataset Status],TRACKER!$H$16) +COUNTIFS(ChartsM6[Lead],"",ChartsM6[Dataset Status],TRACKER!$H$16) +COUNTIFS(ChartsM7[Lead],"",ChartsM7[Dataset Status],TRACKER!$H$16) +COUNTIFS(ChartsM8[Lead],"",ChartsM8[Dataset Status],TRACKER!$H$16)) -> 5 | I22: =(COUNTIFS(ChartsM1[Lead],"",ChartsM1[Dataset Status],TRACKER!$I$16) +COUNTIFS(ChartsM2[Lead],"",ChartsM2[Dataset Status],TRACKER!$I$16) +COUNTIFS(ChartsM3[Lead],"",ChartsM3[Dataset Status],TRACKER!$I$16) +COUNTIFS(ChartsM4[Lead],"",ChartsM4[Dataset Status],TRACKER!$I$16) +COUNTIFS(ChartsM5[Lead],"",ChartsM5[Dataset Status],TRACKER!$I$16) +COUNTIFS(ChartsM6[Lead],"",ChartsM6[Dataset Status],TRACKER!$I$16) +COUNTIFS(ChartsM7[Lead],"",ChartsM7[Dataset Status],TRACKER!$I$16) +COUNTIFS(ChartsM8[Lead],"",ChartsM8[Dataset Status],TRACKER!$I$16)) -> 0 | J22: =(COUNTIFS(ChartsM1[Lead],"",ChartsM1[Dataset Status],TRACKER!$J$16) +COUNTIFS(ChartsM2[Lead],"",ChartsM2[Dataset Status],TRACKER!$J$16) +COUNTIFS(ChartsM3[Lead],"",ChartsM3[Dataset Status],TRACKER!$J$16) +COUNTIFS(ChartsM4[Lead],"",ChartsM4[Dataset Status],TRACKER!$J$16) +COUNTIFS(ChartsM5[Lead],"",ChartsM5[Dataset Status],TRACKER!$J$16) +COUNTIFS(ChartsM6[Lead],"",ChartsM6[Dataset Status],TRACKER!$J$16) +COUNTIFS(ChartsM7[Lead],"",ChartsM7[Dataset Status],TRACKER!$J$16) +COUNTIFS(ChartsM8[Lead],"",ChartsM8[Dataset Status],TRACKER!$J$16)) -> 2 | K22: =(COUNTIFS(ChartsM1[Lead],"",ChartsM1[Dataset Status],TRACKER!$K$16) +COUNTIFS(ChartsM2[Lead],"",ChartsM2[Dataset Status],TRACKER!$K$16) +COUNTIFS(ChartsM3[Lead],"",ChartsM3[Dataset Status],TRACKER!$K$16) +COUNTIFS(ChartsM4[Lead],"",ChartsM4[Dataset Status],TRACKER!$K$16) +COUNTIFS(ChartsM5[Lead],"",ChartsM5[Dataset Status],TRACKER!$K$16) +COUNTIFS(ChartsM6[Lead],"",ChartsM6[Dataset Status],TRACKER!$K$16) +COUNTIFS(ChartsM7[Lead],"",ChartsM7[Dataset Status],TRACKER!$K$16) +COUNTIFS(ChartsM8[Lead],"",ChartsM8[Dataset Status],TRACKER!$K$16)) -> 1
B23: TOTAL | E23: =SUM(E15:E22) -> 155 | F23: =SUM(F17:F22) -> 19 | G23: =SUM(G17:G22) -> 4 | H23: =SUM(H17:H22) -> 21 | I23: =SUM(I17:I22) -> 0 | J23: =SUM(J17:J22) -> 84 | K23: =SUM(K17:K22) -> 4 | V23: =N23/$E23 -> 0 | W23: =O23/$E23 -> 0 | X23: =P23/$E23 -> 0

Sheet Links
A1: Title | B1: Lead | C1: Link
A2: Module 1. Introduction to Sustainable Energy for Development | C2: https://www.figma.com/design/G63dbqCKnazZenINIwtfY1/SEA_Modules-with-new-templates--1-4-?node-id=1-3&p=f&t=15mvoon4RjwZLIC5-0
A3: Module 2. Energy Access and Inclusive Energy Services | B3: Shadé
A4: Module 3. Just Energy Transition | B4: Danae
A5: Module 4. Sustainable Energy Finance | B5: Adam
A6: Module 5. Intersectionality and Energy Policy | B6: Farida | C6: https://www.figma.com/design/AFNWazZePMsFoFYNajOESM/SEA_Modules-with-new-templates--5-8-?node-id=2388-81&t=8lQv8NwY8k2geRUP-0
A7: Module 6. Climate-Energy Nexus
A8: Module 7. Data in Sustainable Energy | B8: Danae
A9: Module 8. Innovation and Future of Renewable Energy | B9: Shadé
A11: OV Graphic Development - Figma file | B11: SiNae | C11: https://www.figma.com/design/1MhqUWjCIcKip6jthZgla7/%5BOV%5D-SEA-Graphic-Development-Task?node-id=0-1&p=f&t=TAGe9NlhcM2y1Vqf-0
A13: Datasets - Infographics with Data | B13: Danae | C13: https://undp.sharepoint.com/:x:/r/sites/SEHCoreTeam/Shared%20Documents/General/04.%20Sustainable%20Energy%20Academy/SEA%20Charts%20and%20Infographics/Datasets/Datasets%20-%20Infographics%20with%20Data.xlsx?d=w6d11da9e3dab40f6b27c20158828a094&csf=1&web=1&e=KqVtlB

Sheet Screenshots
A2: Module | B2: Figure ID | C2: Title | D2: Screenshot | E2: New Screenshot
A3: =MID(B3,2,1) -> 1 | B3: M1_C1_2 | C3: The Human Development Index (HDI) and energy use per capita, 2019 | D3: #VALUE!
A4: =MID(B4,2,1) -> 1 | B4: M1_C1_3 | C4: Global energy flows in the NZE Scenario (2021) | D4: #VALUE!
A5: =MID(B5,2,1) -> 1 | B5: M1_C1_5 | C5: Global fossil fuel consumption | D5: #VALUE!
A6: =MID(B6,2,1) -> 1 | B6: M1_C1_6 | C6: Energy use per person | D6: #VALUE!
A7: =MID(B7,2,1) -> 1 | B7: M1_C1_7 | C7: Global CO2 emissions from energy combustion and industrial processes and their annual change, 1900-2022 | D7: #VALUE!
A8: =MID(B8,2,1) -> 1 | B8: M1_C1_8 | C8: Energy and Climate Change | D8: #VALUE! | E8: #VALUE!
A9: =MID(B9,2,1) -> 1 | B9: M1_C1_9 | C9: Exhibit 1: Energy system losses from primary to useful, 2019 | D9: #VALUE!
A10: =MID(B10,2,1) -> 1 | B10: M1_C1_10 | C10: Global energy demand | D10: #VALUE!
A11: =MID(B11,2,1) -> 1 | B11: M1_C1_12 | C11: Share of renewable sources in final energy consumption and by end use, 2015 and 2021 (percentage) | D11: #VALUE!
A12: =MID(B12,2,1) -> 1 | B12: M1_C1_13 | C12: Installed capacity for renewable electricity generation, 2015 and 2022 (watts per capita) | D12: #VALUE!
A13: =MID(B13,2,1) -> 1 | B13: M1_C1_14 | C13: FIGURE 1.2 Energy-related CO2 emission trajectories based on past COP announcements, PES and the 1.5°C Scenario | D13: #VALUE!
A14: =MID(B14,2,1) -> 1 | B14: M1_C1_15 | C14: The Energy System We Need: Energy Flow in 2050 in a 1.5° aligned scenario | D14: #VALUE!
A15: =MID(B15,2,1) -> 1 | B15: M1_C3_17 | C15: Energy Access in LDCs and Conflict Affected Countries within the Arab States Region | D15: #VALUE!
A16: =MID(B16,2,1) -> 1 | B16: M1_C3_18 | C16: Share of Population with Electricity Access and Clean Cooking Access in the Arab Region | D16: #VALUE!
A17: =MID(B17,2,1) -> 1 | B17: M1_C3_19 | C17: Inflation by sector | D17: #VALUE!
A18: =MID(B18,2,1) -> 1 | B18: M1_C3_20 | C18: Total Energy Subsidies Value in Some Arab Countries | D18: #VALUE!
A19: =MID(B19,2,1) -> 1 | B19: M1_C3_21 | C19: Renewable energy produced per source per country, 2022 | D19: #VALUE!
A20: =MID(B20,2,1) -> 1 | B20: M1_C3_22 | C20: Renewable Energy Installed Capacities and Share in the Total Capacity in 2020 | D20: #VALUE!
... A35: =MID(B35,2,1) -> 1 | B35: M1_C3_36 | C35: Nationally determined contributions and net-zero emissions targets | D35: #VALUE!

Sheet Module1
A1: Module | B1: 1
A2: Chapter | B2: # | C2: Figure ID | D2: Title | E2: Screenshot | F2: New Screenshot | G2: Lead | H2: Source (APA) | I2: Footnote | J2: Source Link | K2: Dataset Link | L2: Chart Status | M2: Dataset Status | N2: Category | O2: Chart Type | P2: Apache Possible | Q2: Apache Link | R2: Automation Possible | S2: Notes
A3: 1 | B3: 2 | C3: =_xlfn.CONCAT("M",$B$1,"_C",ChartsM1[[#This Row],[Chapter]],"_",ChartsM1[[#This Row],['#]]) -> M1_C1_2 | D3: The Human Development Index (HDI) and energy use per capita, 2019 | E3: #VALUE! | G3: Zhong | H3: Cleveland, C., & Clifford, H. (2022, September 30) | I3: Sources: Our World in Data; United Nations Development Programme Boston University Institute for Global Sustainability | visualizingenergy.org | CC BY 4.0 | J3: https://visualizingenergy.org/does-more-energy-use-increase-the-level-of-human-development/ | K3: M1_C1_2 | L3: In process | M3: Ready | N3: Chart to recreate | O3: Scatter Chart Categories | P3: Yes | Q3: https://echarts.apache.org/examples/en/editor.html?c=scatter-simple | R3: Yes | S3: Zhong: Apache Example: https://echarts.apache.org/examples/en/editor.html?c=scatter-simple
A4: 1 | B4: 3 | C4: =_xlfn.CONCAT("M",$B$1,"_C",ChartsM1[[#This Row],[Chapter]],"_",ChartsM1[[#This Row],['#]]) -> M1_C1_3 | D4: Global energy flows in the NZE Scenario (2021) | E4: #VALUE! | L4: In process | N4: Chart for Direct Use
A5: 1 | B5: 5 | C5: =_xlfn.CONCAT("M",$B$1,"_C",ChartsM1[[#This Row],[Chapter]],"_",ChartsM1[[#This Row],['#]]) -> M1_C1_5 | D5: Global fossil fuel consumption | E5: #VALUE! | L5: In process | N5: Chart for Direct Use
A6: 1 | B6: 6 | C6: =_xlfn.CONCAT("M",$B$1,"_C",ChartsM1[[#This Row],[Chapter]],"_",ChartsM1[[#This Row],['#]]) -> M1_C1_6 | D6: Energy use per person | E6: #VALUE! | L6: In process | N6: Chart for Direct Use
A7: 1 | B7: 7 | C7: =_xlfn.CONCAT("M",$B$1,"_C",ChartsM1[[#This Row],[Chapter]],"_",ChartsM1[[#This Row],['#]]) -> M1_C1_7 | D7: Global CO2 emissions from energy combustion and industrial processes and their annual change, 1900-2022 | E7: #VALUE! | G7: Zhong | H7: IEA (2023, p.5) | J7: https://iea.blob.core.windows.net/assets/3c8fa115-35c4-4474-b237-1b00424c8844/CO2Emissionsin2022.pdf | K7: M1_C1_7 | L7: In process | M7: Ready | N7: Chart to recreate | O7: Line Chart | P7: Yes | Q7: https://echarts.apache.org/examples/en/editor.html?c=line-simple | R7: Yes | S7: Yevgen's note I would add here a target of Paris Agreement on limiting the emissions, e.g. by adding a net zero point in 2050 Zhong: Apache Example: https://echarts.apache.org/examples/en/editor.html?c=line-simple; https://echarts.apache.org/examples/en/editor.html?c=bar-simple Frederick's Note: Should this plot be created as one Infographic comprised of both the line and bar chart or should two seperate charts be created. If yes, please open a new row for that.
A8: 1 | B8: 8 | C8: =_xlfn.CONCAT("M",$B$1,"_C",ChartsM1[[#This Row],[Chapter]],"_",ChartsM1[[#This Row],['#]]) -> M1_C1_8 | D8: Energy and Climate Change | E8: #VALUE! | F8: #VALUE! | G8: Zhong | H8: Stanford Doerr School of Sustainability (n.d.) via Climate Watch (2024) | I8: Pie chart showing the sources of GHG emissions by sector in 2021. Energy includes Electricity and Heat, Manufacturing and Construction, Transportation, Fugitive Emissions, and Buildings | J8: https://understand-energy.stanford.edu/current-energy-landscape | K8: M1_C1_8 | L8: In process | M8: Ready | N8: Chart to recreate | O8: Pie chart | P8: Yes | Q8: https://echarts.apache.org/examples/en/editor.html?c=pie-simple | R8: Yes | S8: Zhong: Apache Example: https://echarts.apache.org/examples/en/editor.html?c=pie-simple
A9: 1 | B9: 9 | C9: =_xlfn.CONCAT("M",$B$1,"_C",ChartsM1[[#This Row],[Chapter]],"_",ChartsM1[[#This Row],['#]]) -> M1_C1_9 | D9: Exhibit 1: Energy system losses from primary to useful, 2019 | E9: #VALUE! | H9: Walter, D., Bond, K., Lovins, A., Speelman, L., Gulli, C., & Butler-Sloss, S. (2024) | L9: In process | N9: Chart for Direct Use
A10: 1 | B10: 10 | C10: =_xlfn.CONCAT("M",$B$1,"_C",ChartsM1[[#This Row],[Chapter]],"_",ChartsM1[[#This Row],['#]]) -> M1_C1_10 | D10: Global energy demand | E10: #VALUE! | G10: Zhong | H10: ExxonMobil (2024) | I10: Source: Smil, Energy Transitions (1900-1960), 2024 ExxonMobil Global Outlook (1970-2050) | J10: https://corporate.exxonmobil.com/sustainability-and-reports/global-outlook/energy-demand-drivers | K10: M1_C1_10 | L10: In process | M10: Ready | N10: Chart to recreate | O10: Bar Chart Stacked Vertical | P10: Yes | Q10: https://echarts.apache.org/examples/en/editor.html?c=bar-stack | R10: Yes | S10: Zhong: Data points prior to 2000 were manually extracted (estimates). Data points from 2000 to 2050 are from the ExxonMobil Global Outlook (2024): https://corporate.exxonmobil.com/-/media/global/files/global-outlook/2024/global-outlook-data-2024.xlsx Apache Example: https://echarts.apache.org/examples/en/editor.html?c=bar-stack
A11: 1 | B11: 12 | C11: =_xlfn.CONCAT("M",$B$1,"_C",ChartsM1[[#This Row],[Chapter]],"_",ChartsM1[[#This Row],['#]]) -> M1_C1_12 | D11: Share of renewable sources in final energy consumption and by end use, 2015 and 2021 (percentage) | E11: #VALUE! | G11: Zhong | H11: United Nations Statistics Division (n.d.) | J11: https://unstats.un.org/sdgs/report/2024/Goal-07/ | K11: M1_C1_12 | L11: In process | M11: Ready | N11: Chart to recreate | O11: Bar Chart Categories Horizontal | P11: Yes | Q11: https://echarts.apache.org/examples/en/editor.html?c=bar-y-category-stack | R11: Yes | S11: Zhong: Apache Example: https://echarts.apache.org/examples/en/editor.html?c=bar-y-category-stack Note Frederick: Grouped Stacked Bar Chart changed to Grouped Bar Chart in Dataset
A12: 1 | B12: 13 | C12: =_xlfn.CONCAT("M",$B$1,"_C",ChartsM1[[#This Row],[Chapter]],"_",ChartsM1[[#This Row],['#]]) -> M1_C1_13 | D12: Installed capacity for renewable electricity generation, 2015 and 2022 (watts per capita) | E12: #VALUE! | G12: Zhong | H12: United Nations Statistics Division (n.d.) | J12: https://unstats.un.org/sdgs/report/2024/Goal-07/ | K12: M1_C1_13 | L12: In process | M12: Ready | N12: Chart to recreate | O12: Bar Chart Categories Horizontal | P12: Yes | Q12: https://echarts.apache.org/examples/en/editor.html?c=bar-y-category | R12: Yes | S12: Zhong: Apache Example: https://echarts.apache.org/examples/en/editor.html?c=bar-y-category
A13: 1 | B13: 14 | C13: =_xlfn.CONCAT("M",$B$1,"_C",ChartsM1[[#This Row],[Chapter]],"_",ChartsM1[[#This Row],['#]]) -> M1_C1_14 | D13: Energy-related CO2 emission trajectories based on past COP announcements, PES and the 1.5°C Scenario | E13: #VALUE! | G13: Zhong | H13: IRENA (2024, p.26) | I13: Notes: COP announcements trajectory based on data from (Meinshausen et al., 2023); GtCO2 = gigatonne of carbon dioxide; PES = Planned Energy Scenario; COP = conference of the parties (United Nations Climate Change Conference). | J13: https://www.irena.org/-/media/Files/IRENA/Agency/Publication/2024/Nov/IRENA_World_energy_transitions_outlook_2024.pdf | L13: Pending | M13: Pending | N13: Chart to recreate | O13: Line Chart Stacked | P13: Yes | Q13: https://echarts.apache.org/examples/en/editor.html?c=line-stack | R13: Yes | S13: Zhong: Accordint to the footnote, the original data source is Meinshausen, et al. (2023), “NDC factsheets”, 01 December 2023, https://www.climate-resource.com/ tools/ndcs However, I cannot locate the exact data points to replicate the line chart.
A14: 1 | B14: 15 | C14: =_xlfn.CONCAT("M",$B$1,"_C",ChartsM1[[#This Row],[Chapter]],"_",ChartsM1[[#This Row],['#]]) -> M1_C1_15 | D14: The Energy System We Need: Energy Flow in 2050 in a 1.5° aligned scenario | E14: #VALUE! | G14: Ahmad | L14: Pending | M14: Pending | N14: Chart for Direct Use | S14: File Housing Plots is available in a zip folder that is 3GB, downloading, pending
A15: 3 | B15: 17 | C15: =_xlfn.CONCAT("M",$B$1,"_C",ChartsM1[[#This Row],[Chapter]],"_",ChartsM1[[#This Row],['#]]) -> M1_C3_17 | D15: Energy Access in LDCs and Conflict Affected Countries within the Arab States Region | E15: #VALUE! | L15: Pending | M15: Pending | N15: Infographic WITH Data
A16: 3 | B16: 18 | C16: =_xlfn.CONCAT("M",$B$1,"_C",ChartsM1[[#This Row],[Chapter]],"_",ChartsM1[[#This Row],['#]]) -> M1_C3_18 | D16: Share of Population with Electricity Access and Clean Cooking Access in the Arab Region | E16: #VALUE! | G16: Ahmad | H16: Arab future energy index 2023 | United Nations Development Programme. (n.d.). https://www.undp.org/arab-states/publications/arab-future-energy-index-2023 | J16: https://www.undp.org/arab-states/publications/arab-future-energy-index-2023 | K16: https://undp.sharepoint.com/:x:/r/sites/SEHCoreTeam/Shared%20Documents/General/04.%20Sustainable%20Energy%20Academy/SEA%20Charts%20and%20Infographics/SEA%20-%20Charts/Datasets/Module%201%20-%20Datasets%20for%20Charts.xlsx?d=w3f72cf2573e04beea03a0913cad89118&csf=1&web=1&e=ScPEJb&nav=MTVfe0VFNjdDQzdCLTRFQTktNEVFMi05Q0IzLUQ1MzU0QjRCQThFQn0 | L16: In process | M16: Ready | N16: Chart to recreate | O16: Bar Chart categories vertical | P16: Yes | R16: Yes
A17: 3 | B17: 19 | C17: =_xlfn.CONCAT("M",$B$1,"_C",ChartsM1[[#This Row],[Chapter]],"_",ChartsM1[[#This Row],['#]]) -> M1_C3_19 | D17: Inflation by sector | E17: #VALUE! | G17: Zhong | H17: Human Rights Watch (n.d.) | J17: https://www.hrw.org/news/2023/03/09/lebanon-electricity-crisis-exacerbates-poverty-inequality | L17: Pending | M17: Pending | N17: Chart to recreate | O17: Line Chart multi | P17: Yes | Q17: https://echarts.apache.org/examples/en/editor.html?c=line-stack | R17: Yes | S17: Zhong: I cannot locate the exact data points to replicate the line chart.
A18: 3 | B18: 20 | C18: =_xlfn.CONCAT("M",$B$1,"_C",ChartsM1[[#This Row],[Chapter]],"_",ChartsM1[[#This Row],['#]]) -> M1_C3_20 | D18: Total energy subsides value in some of Arab countries (Real 2020 million USD) | E18: #VALUE! | G18: Zhong | H18: Regional Center for Renewable Energy and Energy Efficiency (2023, p.61) | J18: https://www.undp.org/sites/g/files/zskgke326/files/2023-09/final_afex_2023-_18-9-2023.pdf | K18: M1_C3_20 | L18: In process | M18: Ready | N18: Chart to recreate | O18: Bar chart categories horizontal | P18: Yes | Q18: https://echarts.apache.org/examples/en/editor.html?c=bar-y-category | R18: Yes | S18: Zhong: I cannot locate the original chart in green but I was able to find the source chart in the PDF report (p.61): https://www.undp.org/sites/g/files/zskgke326/files/2023-09/final_afex_2023-_18-9-2023.pdf
A19: 3 | B19: 21 | C19: =_xlfn.CONCAT("M",$B$1,"_C",ChartsM1[[#This Row],[Chapter]],"_",ChartsM1[[#This Row],['#]]) -> M1_C3_21 | D19: Renewable energy produced per source per country, 2022 | E19: #VALUE! | G19: Zhong | H19: Regional Center for Renewable Energy and Energy Efficiency (2023, p.36) | J19: https://www.undp.org/sites/g/files/zskgke326/files/2023-09/final_afex_2023-_18-9-2023.pdf | K19: M1_C3_21 | L19: In process | M19: Ready | N19: Chart to recreate | O19: Bar chart stacked vertical | P19: Yes | Q19: https://echarts.apache.org/examples/en/editor.html?c=bar-y-category | R19: Yes | S19: Zhong: I cannot locate the original chart in green but I was able to find the source chart in the PDF report (p.36): https://www.undp.org/sites/g/files/zskgke326/files/2023-09/final_afex_2023-_18-9-2023.pdf
A20: 3 | B20: 23 | C20: =_xlfn.CONCAT("M",$B$1,"_C",ChartsM1[[#This Row],[Chapter]],"_",ChartsM1[[#This Row],['#]]) -> M1_C3_23 | D20: National Renewable Energy Targets in the Arab Region | E20: #VALUE! | L20: In process | N20: Chart for Direct Use
A21: 3 | B21: 25 | C21: =_xlfn.CONCAT("M",$B$1,"_C",ChartsM1[[#This Row],[Chapter]],"_",ChartsM1[[#This Row],['#]],"_1") -> M1_C3_25_1 | D21: Average cost of natural disasters and energy prices in the Caribbean | E21: #VALUE! | G21: Gabriela | H21: Guerson, A., Morsink, J., and Muñoz, S. (2023). Caribbean Climate Crisis Demands Urgent Action by Governments and Investors. IMF Blog. | I21: Sources: EM-DAT, World Economic Outlook; and IMF staff calculations. _x000D_globalpetrolprices.com. Prices for gasoline and diesel as on 20 February, 2023; electricity for June 2022. Note: Left panel - Three subgroups are identified as weather-related natural disasters climatological (incl. drought, wildfire), hydrological (incl. flood, landslide), and meteorological (storm, extreme temperature). Groups of WHD, Pacific and rest of the world are exclusive. LAC = Latin America and the Caribbean; CAPDR = Central _x000D_America, Panama,and the Dominican Republic; RoW = Rest of world. | J21: https://www.imf.org/en/Blogs/Articles/2023/06/27/caribbean-climate-crisis-demands-urgent-action-by-governments-and-investors | K21: M1_C3_25_1 | L21: In process | M21: Ready | N21: Chart to recreate | O21: Bar Chart Vertical | P21: Yes | Q21: Db1. https://echarts.apache.org/examples/en/editor.html?c=pictorialBar-bar-transition; Db2. https://echarts.apache.org/examples/en/editor.html?c=dataset-simple1 | R21: Yes | S21: I've made 2 diferent Db for the combined chart, here is the second one: M1_C3_25_2
A22: 3 | B22: 25 | C22: =_xlfn.CONCAT("M",$B$1,"_C",ChartsM1[[#This Row],[Chapter]],"_",ChartsM1[[#This Row],['#]],"_2") -> M1_C3_25_2 | D22: Average cost of natural disasters and energy prices in the Caribbean | E22: #VALUE! | G22: Gabriela | H22: Guerson, A., Morsink, J., and Muñoz, S. (2023). Caribbean Climate Crisis Demands Urgent Action by Governments and Investors. IMF Blog. | I22: Sources: EM-DAT, World Economic Outlook; and IMF staff calculations. _x000D_globalpetrolprices.com. Prices for gasoline and diesel as on 20 February, 2023; electricity for June 2022. Note: Left panel - Three subgroups are identified as weather-related natural disasters climatological (incl. drought, wildfire), hydrological (incl. flood, landslide), and meteorological (storm, extreme temperature). Groups of WHD, Pacific and rest of the world are exclusive. LAC = Latin America and the Caribbean; CAPDR = Central _x000D_America, Panama,and the Dominican Republic; RoW = Rest of world. | J22: https://www.imf.org/en/Blogs/Articles/2023/06/27/caribbean-climate-crisis-demands-urgent-action-by-governments-and-investors | K22: M1_C3_25_2 | L22: In process | M22: Ready | N22: Chart to recreate | O22: Bar Chart categories vertical | P22: Yes | Q22: Db1. https://echarts.apache.org/examples/en/editor.html?c=pictorialBar-bar-transition; Db2. https://echarts.apache.org/examples/en/editor.html?c=dataset-simple1 | R22: Yes | S22: I've made 2 diferent Db for the combined chart, here is the second one: M1_C3_25_2
A23: 3 | B23: 25 | C23: =_xlfn.CONCAT("M",$B$1,"_C",ChartsM1[[#This Row],[Chapter]],"_",ChartsM1[[#This Row],['#]]) -> M1_C3_25 | D23: Scenarios for green jobs creation in Latin America and the Caribbean, 2020-2030 | E23: #VALUE! | G23: Gabriela | H23: OECD et al. (2022), Latin American Economic Outlook 2022: Towards a Green and Just Transition, OECD Publishing, Paris, https://doi.org/10.1787/3d5554fc-en | I23: Notes: LAC countries included are Argentina, Bolivia, Brazil, Colombia, Ecuador, Guatemala, Mexico, Paraguay and Uruguay. The data refer to an unweighted average over the countries’ forecasts. Green sectors are defined in each country by first identifying the number of green tasks that workers perform in their occupations and then by examining the top ten industries across which those jobs are distributed. The baseline scenario assumes that, in each green sector, value added and employment will follow the same dynamic as in the past ten years. The counterfactual scenarios are defined according to the impact of a green policy that aims to boost investment in fixed and human capital, with a positive impact on value‑added growth in each green sector. The high‑impact scenario assumes that the value added in each sector will increase by 3 percentage points per year, adjusting to the new equilibrium. The medium‑impact scenario assumes that the value added will increase by 2 percentage points per year, while the low‑impact scenario assumes it will decrease by 1 percentage point per year. In all forecasts, total factor productivity will increase by 1 percentage point due to lower climate damages and new technology‑induced change. Employment change is forecast using the estimated short‑term elasticity to the value added, applying a panel dynamic model, defined by each sector and country, in the last ten years. Sources: Authors’ estimates based on Labour Force Surveys, National Accounts data by industries, (Vona et al., 2018[13]) and (Hardy, Keister and Lewandowski, 2018[14]). | J23: https://www.oecd.org/en/publications/latin-american-economic-outlook-2022_3d5554fc-en.html | K23: M1_C3_25 | L23: In process | M23: Ready | N23: Chart to recreate | O23: Line Chart Multi | P23: Yes | Q23: https://echarts.apache.org/examples/en/editor.html?c=line-race | R23: Yes | S23: Footnotes are the author's
A24: 3 | B24: 26 | C24: =_xlfn.CONCAT("M",$B$1,"_C",ChartsM1[[#This Row],[Chapter]],"_",ChartsM1[[#This Row],['#]]) -> M1_C3_26 | D24: Clean Energy Equlty Index (CEEI) | E24: #VALUE! | J24: https://undpgeohub.org/maps/338 | L24: In process | N24: Maps to recreate
A25: 3 | B25: 27 | C25: =_xlfn.CONCAT("M",$B$1,"_C",ChartsM1[[#This Row],[Chapter]],"_",ChartsM1[[#This Row],['#]]) -> M1_C3_27 | D25: Crude oil production, global ranking, 2022 | E25: #VALUE! | G25: Gabriela | H25: IEA. (2022). Africa - Oil: Crude oil production, global ranking, 2022. | I25: Source: World Energy Balances | J25: https://www.iea.org/regions/africa/oil | K25: M1_C3_27 | L25: In process | M25: Ready | N25: Chart to recreate | O25: Morphing between Map and Bar | P25: Yes | Q25: https://echarts.apache.org/examples/en/editor.html?c=map-bar-morph | R25: Yes
A26: 3 | B26: 28 | C26: =_xlfn.CONCAT("M",$B$1,"_C",ChartsM1[[#This Row],[Chapter]],"_",ChartsM1[[#This Row],['#]]) -> M1_C3_28 | D26: Total electricity production, regional ranking, 2022 | E26: #VALUE! | G26: Gabriela | H26: IEA. (2022). Africa - Electricity: Total electricity production, regional ranking, 2022 | I26: Source: Electricity Information | J26: https://www.iea.org/regions/africa/electricity | K26: M1_C3_28 | L26: In process | M26: Ready | N26: Chart to recreate | O26: Morphing between Map and Bar | P26: Yes | Q26: https://echarts.apache.org/examples/en/editor.html?c=map-bar-morph | R26: Yes
A27: 3 | B27: 29 | C27: =_xlfn.CONCAT("M",$B$1,"_C",ChartsM1[[#This Row],[Chapter]],"_",ChartsM1[[#This Row],['#]]) -> M1_C3_29 | D27: Total electricity production, regional ranking, 2022 | E27: #VALUE! | G27: Gabriela | H27: IEA. (2022). Africa - Electricity: Total electricity production, global ranking, 2022 | I27: Source: Electricity Information | J27: https://www.iea.org/regions/africa/electricity | K27: M1_C3_29 | L27: In process | M27: Ready | N27: Chart to recreate | O27: Morphing between Map and Bar | P27: Yes | Q27: https://echarts.apache.org/examples/en/editor.html?c=map-bar-morph | R27: Yes | S27: What is the difference between 28 and 29?
A28: 1 | B28: 37 | C28: =_xlfn.CONCAT("M",$B$1,"_C",ChartsM1[[#This Row],[Chapter]],"_",ChartsM1[[#This Row],['#]]) -> M1_C1_37 | D28: Share of renewable electricity generation by technology, 2000-2030 | E28: #VALUE! | G28: Gabriela | H28: IEA. (2023). Share of renewable electricity generation by technology, 2000-2030 | I28: Notes: Electricity generation from wind and solar PV indicate potential generation including current curtailment rates. However, it does not project future curtailment of wind and solar PV, which may be significant in a few countries by 2028. | J28: https://www.iea.org/data-and-statistics/charts/share-of-renewable-electricity-generation-by-technology-2000-2030 | K28: M1_C1_37 | L28: Pending | M28: Ready | N28: Chart to recreate | O28: Line Chart Multi | P28: Yes | Q28: https://echarts.apache.org/examples/en/editor.html?c=line-race | R28: Yes
A29: 3 | B29: 30 | C29: =_xlfn.CONCAT("M",$B$1,"_C",ChartsM1[[#This Row],[Chapter]],"_",ChartsM1[[#This Row],['#]]) -> M1_C3_30 | D29: Evolution of electricity generation sources in Asia Pacific since 2000 | E29: #VALUE! | G29: Divya | H29: International Energy Agency. (n.d.). Electricity – Asia Pacific. IEA. Retrieved June 24, 2025, from https://www.iea.org/regions/asia-pacific/electricity | J29: https://www.iea.org/regions/africa/electricity | K29: https://www.iea.org/regions/asia-pacific/electricity | L29: In process | M29: Ready | N29: Chart to recreate | O29: Line Chart Multi | P29: Yes | Q29: https://echarts.apache.org/examples/data/thumb/line-race.webp?_v_=1749990823367 | R29: Yes
