Workbook

Sheet Lessons
A1: Lesson Number | B1: Lesson Title | C1: Chapter Title | D1: Module Title | E1: Description | F1: Key Takeaways | G1: Key Concept | H1: Concept Definition | I1: Resource Title | J1: Resource Description | K1: Resource Source | L1: Resource Link | M1: Resource ID | N1: Status | O1: Notes
A2: 1.1.1 | B2: The Great Energy Dilemma: Paradoxes of Sustainable Development | C2: Introduction to Energy Systems | D2: Intro to Sustainable Energy for Development | E2: Understanding the role of sustainable energy for human well-being and development | F2: Energy fuels development, and development is essential for sustaining human life and well-being. Yet the current processes and infrastructure through which energy is produced and used are rapidly degrading the livability of the planet. This creates the central dilemma of energy: expanding energy access at scale while averting catastrophic climate change by rapidly reducing GHG emissions. The decisions we make today will shape the well-being of future generations, starting with the lives and livelihoods of people in climate-vulnerable and low-income countries. | G2: energy for development | H2: Energy for development refers to the provision and use of energy resources to support economic growth, improve living standards, and enhance social well-being in communities, particularly in developing regions. | I2: Tracking SDG7: The Energy Progress Report 2025 | J2: This report provides insights into the energy-development nexus, the dilemma created by current energy systems—especially in low-income and climate-vulnerable countries—and the latest data and insights into progress towards SDG7. | K2: ESMAP/ Joint Custodian Agencies (IEA, IRENA, UNSD, World Bank, WHO) | L2: https://iea.blob.core.windows.net/assets/fc78dc81-8167-4c41-b8a6-e3386fecf957/TrackingSDG7TheEnergyProgressReport%2C2025.pdf | M2: 1111 | N2: Refined
A3: 1.1.1 | F3: Clean energy is advancing, but the current unsustainable energy system, still dominated by fossil fuels, remains vulnerable, unequal, and politically constrained, while many regions with severe energy-access deficits remain underserved. Although renewable energy infrastructure is increasingly technically feasible and financially viable, political-economic barriers continue to delay the urgent and just transition needed, with investment still not flowing proportionately to regions with vast renewable potential and urgent development needs. These paradoxes show that the challenges are not only technical and financial, but also political and ethical. | G3: energy trilemma | H3: The energy trilemma refers to the challenge of balancing three key objectives in energy policy: ensuring energy security, promoting environmental sustainability, and providing energy equity or affordability for all consumers. | I3: Transformations within reach: Pathways to a sustainable and resilient world - RETHINKING ENERGY SOLUTIONS | J3: This report highlights the global energy transition paradox: despite rapid progress in renewable energy, the transition remains off track, fossil fuels continue to dominate, and many countries with severe energy-access needs and strong renewable potential still struggle to attract clean energy investment | L3: https://pure.iiasa.ac.at/id/eprint/16820/1/Energy-NEW.pdf | M3: 1112 | N3: Refined
A4: 1.1.1 | F4: We need a just, decentralized, clean, and renewable energy system that is less vulnerable to global shocks. Supported by digital tools, AI, data, pipelines of bankable projects, and fair financing, such a system can deliver inclusive and sustainable development across sectors while helping to achieve the Paris Agreement goals by 2050 | G4: Paris Areement Goals | H4: The Paris Agreement goals refer to the international commitments made by countries to limit global warming to well below 2°C above pre-industrial levels, pursue efforts to limit warming to 1.5°C, and enhance the ability to adapt to climate change impacts. | I4: The Paris Agreement at Ten Years: Expert Views on Progress and Challenges for Climate Change Mitigation The Paris Agreement at Ten Years | J4: This report examines the progress and remaining challenges of the Paris Agreement ten years after its adoption. It supports the takeaway by showing why clean, inclusive, and climate-aligned energy systems are needed to accelerate mitigation and help achieve long-term climate goals | K4: Organisation for Economic Co-operation and Development (OECD) | L4: https://www.oecd.org/en/publications/the-paris-agreement-at-ten-years_c5f214dc-en.html | M4: 1113 | N4: Refined
A5: 1.1.2 | B5: The Complexities of Global Energy Use | E5: Exploring the benefits of sustainable energy and examining the energy transition | F5: Disparities in reliable energy access and energy consumption persist across regions and within countries, shaping human development, access to services, and economic opportunities. Meanwhile, rising demand from population growth, urbanization, and industrialization turns the energy trilemma into a complex practical challenge of managing the delicate balance between economic development, environmental protection, and community well-being. | G5: nationally determined contributions | H5: Nationally Determined Contributions (NDCs) are the climate action plans that countries submit to outline their commitments to reduce greenhouse gas emissions and adapt to climate change, as part of the Paris Agreement. | I5: World Energy Outlook 2025 | J5: The 2025 edition of the IEA’s World Energy Outlook examines global energy trends and possible energy futures, with implications for energy security, access, affordability, sustainability, and emissions. It supports the lesson’s focus on the practical complexities of global energy use. . The 2024 edition of the IEA’s World Energy Outlook discusses the challenges of energy access, with 750 million people lacking electricity and over 2 billion without clean cooking fuels, predominantly in sub-Saharan Africa. The report also addresses the current trajectory of global energy transitions, warning of a potential rise of 2.4°C in global temperatures by 2100 if current policies persist. | K5: IEA | L5: https://iea.blob.core.windows.net/assets/9753df19-0a71-422a-b725-012c555763b3/WorldEnergyOutlook2025.pdf | M5: 1121 | N5: Confirmed
A6: 1.1.2 | F6: The complexities of the current fossil-fuel-centric energy system lie in its systemic risks: high carbon intensity, inefficiency, fragile infrastructure, political instability, price volatility, and supply-chain disruptions. These risks undermine the foundations of energy security. | G6: sustainable energy & renewable energy | H6: Sustainable energy refers to energy sources that are environmentally friendly and can be maintained over the long term without depleting resources or harming the ecosystem. Renewable energy is a subset of sustainable energy that comes from natural processes that are continuously replenished, such as solar, wind, and hydro power. | I6: Geopolitics of the Energy Transition: Energy Security | J6: This report examines how energy security risks are changing as the world moves away from fossil-fuel dependence. It supports the takeaway by explaining how fossil-fuel-centred energy systems create vulnerabilities linked to supply disruption, price volatility, geopolitics, and infrastructure dependence. IRENA’s World Energy Transition Outlook highlights that the global energy transition is falling short, jeopardizing the achievement of the 1.5°C climate goal set at COP21 nearly a decade ago. While there is still time to act, an urgent course correction is essential to realign with this target. Achieving this requires addressing the structural and systemic barriers that continue to hinder progress in the energy transition. | K6: IRENA | L6: https://www.irena.org/-/media/Files/IRENA/Agency/Publication/2024/Apr/IRENA_Geopolitics_transition_energy_security_2024.pdf | M6: 1122 | N6: Confirmed
A7: 1.1.2 | F7: The history of energy systems shows an additive dynamic rather than a truly transitional one, with new energy sources often layered onto existing fossil-fuel systems instead of fully replacing them. A genuine transition must therefore address this complexity through urgent structural reforms, strategic phase-out of polluting energy systems, and planned expansion of diverse, decentralized, and sustainable energy systems. | G7: just energy transition | H7: A just energy transition refers to the shift from fossil fuels to renewable energy sources in a way that is fair and equitable, ensuring that all communities, especially those historically marginalized, benefit from the transition and are not left behind. | I7: Seizing the Moment of Opportunity: Supercharging the New Energy Era of Renewables, Efficiency, and Electrification | J7: This United Nations report explains that renewable energy is growing rapidly, but fossil fuels are not being replaced at the pace and scale needed. It supports the key takeaway that the current energy transition must move beyond adding clean energy capacity and actively reduce fossil-fuel dependence through renewables, efficiency and electrification. | K7: United Nations | L7: https://www.un.org/en/climatechange/moment-opportunity-2025 | M7: 1123 | N7: Confirmed
A8: 1.1.3 | B8: The Sustainable Energy Landscape | E8: This lesson explores the role of sustainable energy as a driver fo development, focusing on the SDGs, specifically SDG 7 as well as the progress made in advancing sustainable development and the energy transition. | F8: Transitioning to sustainable energy brings transformative advantages, such as enhancing energy security by reducing dependence on fossil fuel imports, making energy more affordable through declining renewable costs, improving public health by reducing air pollution, and driving job creation. | G8: Sustainable Energy System | H8: A sustainable energy system provides equitable access to reliable and affordable energy benefits for a growing global population, while conserving finite natural resources and avoiding environmental degradation. | I8: Maximising the Benefits of Energy Action for Good Health, Gender Equality and Decent Work to Leave No one Behind: SDG7 Policy Briefs in Support of the High-Level Political Forum 2025 Towards a Sustainable Energy Future | J8: This 2025 UN SDG7 policy brief compilation explains how sustainable energy action can advance health, gender equality, decent work, inclusion, climate action, and broader sustainable development progress. This report is a primer on the theory behind sustainable energy and offers advice for long-term strategy. This report is a primer on the theory behind sustainable energy and offers advice for long-term strategy. | K8: United Nations Department of Economic and Social Affairs / SDG7 Technical Advisory Group | L8: https://www.un.org/sites/un2.un.org/files/2025_policy_briefs_in_support_of_the_high-level_political_forum-071525b.pdf | M8: 1131 | N8: Suggest deleting this and having 2 instead of 3 (this existing one is from 2001)
A9: 1.1.3 | F9: Renewable energy capacity is expanding at an unprecedented pace, but progress remains uneven and too slow to meet global climate and energy targets, especially in LDCs, LLDCs, and SIDS. Electricity is advancing faster, while heating and transport remain slower to transition. These gaps show the need for more ambitious global transition targets and stronger action, as current efforts remain insufficient to keep global warming within 1.5°C. | G9: SDG7 | H9: The Sustainable Development Goals number 7 refers to: "Ensure access to affordable, reliable, sustainable, and modern energy for all. SDG7 highlights the critical role energy plays in fighting poverty, reducing inequality, and tackling climate change." | I9: Delivering the UAE Consensus | L9: https://www.irena.org/Publications/2025/Oct/UAE-Consensus-2030-tripling-renewables-doubling-efficiency | M9: 1132 | N9: Confirmed
A10: 1.1.3 | F10: A sustainable energy transition must address the economic and social impacts on affected communities, including fossil-fuel-related workers,vulnerable groups, and marginalized communities, to ensure a just and equitable energy transition. A significant gap remains, requiring accelerated policy implementation, technological innovation, and international collaboration to close the emissions gap and meet global climate goals. | I10: Paying for the Paris Agreement: A Primer on Government Options for Financing Nationally Determined Contributions | L10: https://files.wri.org/d8/s3fs-public/2022-11/paying-paris-agreement.pdf?VersionId=Yc.idZ6NMkKMpH42RKGfmZqU.2qOSf23 | M10: 1211 | N10: Confirmed
A11: 1.2.1 | B11: Access to electricity and clean cooking (SDG 7.1) | C11: Interlinkages between Energy and Other SDGs | E11: Catalyzing progress across the SDGs through universal energy access | F11: Reliable electricity is essential for effective healthcare delivery. It enables safe childbirth, vaccine storage, diagnostics, emergency response, lighting, communication, and the operation of essential medical equipment. Without dependable electricity, health facilities cannot provide safe, timely, and quality care. | G11: clean cooking | H11: Clean cooking refers to the use of safe, efficient, and environmentally friendly cooking technologies and fuels that reduce indoor air pollution and minimize health risks, while also lowering greenhouse gas emissions. | I11: SDG7 Interactions | J11: The study provides an overview of interactions at the goal level between SDG7 – the ‘entry level goal’ for this assessment – and the other 16 SDGs. | K11: IIASA PURE | L11: https://pure.iiasa.ac.at/id/eprint/14621/1/SDGs-interactions-7-clean-energy.pdf | M11: 1212 | N11: Confirmed | O11: ✅
A12: 1.2.1 | F12: Clean cooking access improves health, gender equality, and well-being by reducing household air pollution and the time spent collecting fuel and cooking with inefficient methods. Since women and girls often carry a larger share of household cooking and fuel-collection responsibilities, clean cooking solutions can reduce health risks, lower time poverty, and create more opportunities for education, livelihoods, and community participation. | G12: time poverty | H12: Clean cooking, health and gender equality refers to safe and efficient cooking solutions that reduce household air pollution, improve health, and lower the time burden on women and girls, thereby supporting gender equality, education, livelihoods and wider participation. | I12: A Vision for Clean Cooking Access for All | J12: The report evidences that transforming the clean cooking landscape is a complex endeavour with no straight-forward solutions, but one that requires the establishment of clear policies and robust regulatory frameworks as foundational elements for attracting and driving investment in clean cooking projects. | K12: IEA | L12: https://www.iea.org/reports/a-vision-for-clean-cooking-access-for-all | M12: 1213 | N12: Confirmed | O12: ✅
A13: 1.2.1 | F13: Overall, access to reliable, affordable, and clean electricity and cooking solutions should be understood not only as an energy target, but as an enabling condition for wider sustainable development. Energy access supports poverty reduction, food security, health, education,gender equality, clean water, decent work, industry, climate action, and environmental protection.
A14: 1.2.2 | B14: Renewable energy (SDG 7.2) | E14: Leveraging the SDG synergies and navigating the trade-offs in the energy transition | F14: Expanding renewable energy under SDG 7.2 does more than increase clean energy supply. When solar, wind and other renewables replace fossil-fuel-based, water-intensive thermal power generation, they support climate action (SDG 13) and ease pressure on freshwater resources (SDG 6). This can also strengthen food systems (SDG 2), reduce vulnerability in water-stressed communities (SDG 10), protect ecosystems (SDG 15), and, with careful planning of offshore wind, tidal and wave energy, contribute to ocean sustainability (SDG 14). | I14: Addressing Energy’s Interlinkages with other SDGs | J14: This document was prepared in support of the review of the SDGs at the United Nations High-Level Political Forum 2022. This edition takes a closer look at interlinkages between energy and SDG 4 (education), SDG 5 (gender), and SDG 15 (life on land), identifying potential indicators that could help in tracking global progress in these interlinkages. | K14: United Nations | L14: https://sdgs.un.org/publications/report-2022-sdg7-tag-policy-briefs-addressing-energys-interlinkages-other-sdgs-47727 | M14: 1221 | N14: Confirmed | O14: ✅
A15: 1.2.2 | F15: Transitioning to renewable energy can improve air quality and public health.This is especially important in fast-growing urban centres, where air pollution affects health, liveability, and quality of life. When supported by clean public transport, smart grids, energy communities, and local policy action, renewable energy also strengthens urban resilience, linking SDG 7.2 with healthier lives (SDG 3) and sustainable cities (SDG 11). Renewable energy directly reduces air pollution, improving health outcomes especially for those in dense urban centers Improving air quality, and by extension human health, is especially important for those living in the dense urban centers of rapidly developing countries (SDG 3 and SDG 11). | G15: energy value chain | H15: The energy value chain refers to the full range of processes involved in the production, distribution, and consumption of energy, including extraction, generation, transmission, and end-use. | I15: Energy Research and Social Science | L15: https://www.sciencedirect.com/journal/energy-research-and-social-science/vol/135/suppl/C | M15: 1222 | N15: Confirmed
A16: 1.2.2 | F16: Adoption of renewable energy requires resilient infrastructure, innovation, and industrial development. With careful policy intervention, it can create fair local and global value chains and can create jobs throughout the value chain - planning, installation, deployment, maintenance - and drive employment opportunities in other industries. | G16: water-energy-food nexus | H16: The water-energy-food nexus refers to the interconnectedness of water, energy, and food systems, highlighting how the management of one resource affects the others, and emphasizing the need for integrated approaches to ensure sustainability and security in these critical areas. | I16: Building a Nature-positive Energy Transformation - Why a Low-Carbon Economy is Better for People and Nature | J16: This report is builds on existing studies and quantifies and compares 30 environmental and socioeconomic impact metrics in two different energy scenarios for the future. It also presents a framework for establishing the nature-positive energy transformation that is essential to achieving critical climate and sustainable development goals. | K16: WWF | L16: https://wwf.panda.org/wwf_news/?9967866/Building-a-Nature-Positive-Energy-Transformation#:~:text=An%20energy%20system%20powered%20by,human%20health%2C%20biodiversity%20and%20ecosystems. | M16: 1223 | N16: Confirmed | O16: ✅
A17: 1.2.3 | B17: Energy Efficiency (SDG 7.3) | E17: Improving energy efficiency for building sustainable and resilient socieities | F17: With the global population expected to rise to 9 billion by 2050, efficient use of water, food, soil and energy will be essential for food and water security. Energy efficiency can support this shift through measures such as efficient irrigation, improved cooling systems, reduced food losses, better monitoring and more sustainable agro-food chains. In this way, SDG 7.3 connects energy efficiency with water security (SDG 6), food security (SDG 2), climate action (SDG 13) and ecosystem protection (SDG 15). | G17: energy and digitalization | H17: Energy and digitalization refers to the integration of digital technologies into the energy sector, enhancing efficiency, management, and innovation in energy production, distribution, and consumption. | I17: ENERGY - The International Journal | L17: https://www.sciencedirect.com/journal/energy | M17: 1231 | N17: Confirmed
A18: 1.2.3 | F18: As energy access improves and renewable energy systems expand, it becomes equally important to use resources more efficiently especially energy. The COP28 UAE pledge also reflects this by calling for tripling renewable energy capacity and doubling the rate of energy-efficiency improvement by 2030. Waste should not remain only a disposal problem; it can be converted into energy, fertilizer, or other useful materials, supporting circular economy practices. | G18: energy efficiency | H18: Energy efficiency refers to the efficient management of interconnected water, food, energy, and ecosystem systems to reduce resource pressure, lower energy waste, improve agricultural productivity, and support food security without increasing environmental stress. | I18: Energy Efficiency 2025 | J18: Energy Efficiency 2025 is the IEA’s primary annual analysis on global energy efficiency developments, showing recent trends in energy intensity and demand, investment, employment and policy. The report provides sector-specific analysis on industry, buildings, appliances and transport and explores system-wide themes such as emissions reductions, energy security, affordability and competitiveness. This report is launched in parallel with an update to the IEA Energy Efficiency Progress Tracker, which can be accessed through the IEA website. | K18: IEA | L18: https://iea.blob.core.windows.net/assets/23a80bb2-6985-4507-ab99-c1d700f6548b/EnergyEfficiency2025.pdf | M18: 1232 | N18: Confirmed | O18: ✅
A19: 1.2.3 | F19: Digitalization can strengthen energy efficiency by making energy use easier to monitor, manage and improve. In industry, tools such as automation, real-time data, IoT and AI can reduce energy losses, improve productivity and lower emissions. Digital tools in power systems, buildings and cities can also reduce consumption and make efficiency gains more practical under SDG 7.3. | G19: waste-to-energy solutions | I19: Digital Technologies to Implement the UN Sustainable Development Goals | M19: 1233 | N19: Confirmed | O19: ✅
A20: 1.3.1 | B20: Arab States | C20: Regions | E20: sustainable energy in the Arab states | F20: The Arab States have a highly diverse development profile, with countries ranging from very high to low levels of human development. While overall electricity access is relatively high, serious gaps remain in least developed and conflict-affected countries, where limited, damaged or disrupted infrastructure can weaken supply. Climate change is increasing water scarcity and affecting land productivity in a region that depends heavily on food imports. At the same time, electricity quality, affordability and reliability remain major concerns, making the energy challenge broader than access numbers alone. | I20: The Water, Energy and Food Security Nexus in the Arab Region | J20: This report provides an analytical framework to understand the water-energy-food security nexus in the Arab region. It considers climate change and advances a human rights approach. | K20: ESCWA | L20: https://www.unescwa.org/sites/default/files/pubs/pdf/e_escwa_sdpd_15_2_e_0.pdf | M20: 1241 | N20: Confirmed | O20: ✅
A21: 1.3.1 | F21: Although renewables still account for only a small share of the Arab States’ energy mix, the past decade has seen major reforms, rising investment and rapid growth in renewable capacity, reaching around 23.6 GW. At the same time, fossil-fuel subsidies make the transition more difficult by adding fiscal pressure and weakening incentives for cleaner energy. The region’s progress therefore depends not only on expanding renewable capacity, but also on reforming subsidies and creating policy conditions that make the transition financially realistic and feasible. | G21: energy in crisis settings | H21: Energy in crisis settings refers to the provision and management of energy resources in areas affected by emergencies, such as natural disasters, armed conflicts, or humanitarian crises, where access to reliable energy is critical for survival, recovery, and rebuilding efforts. | I21: Renewable Energy Solutions for Crisis-Affected Communities in the Arab Region | J21: This policy brief discusses the importance of energy in crisis contexts and solutions, with a particular focus on decentralized renewable energy. | K21: UNDP | L21: https://www.undp.org/publications/dfs-sustainable-energy-access-crisis-recovery-renewable-energy-solutions-crisis-affected-communities-arab-region | M21: 1242 | N21: Confirmed | O21: ✅
A22: 1.3.1 | F22: Renewable energy investment in the Arab States has grown sharply, rising from about USD 2.2 billion in 2010 to USD 10.9 billion in 2020, alongside new strategies, tariff exemptions and incentives for renewables and energy efficiency. Still, limited finance, fossil-fuel subsidies, human-capacity gaps and weak institutional coordination can slow the transition, especially in conflict-affected settings. A just and inclusive transition needs stronger institutions, skilled people, better coordination and policies that help clean energy and efficiency scale. | I22: Investing in the Future: The Role of Human Capital in Enabling Just Energy Transitions in the Arab Region | J22: This report discusses the importance of human capital in the energy transition, focusing on education, employment, skills development and innovation. | K22: UNESCWA | L22: https://www.unescwa.org/publications/investing-future-human-capital-energy-transitions-arab-region | M22: 1243 | N22: Confirmed | O22: ✅
A23: 1.3.2 | B23: Latin America and the Caribbean | E23: Sustainable energy in Latin America and the Caribbeans | F23: Although Latin America and the Caribbean has a high electricity access rate of 97.6%, this figure hides serious local gaps. The region has abundant renewable resources and one of the cleanest electricity matrices, yet fossil fuels still account for about 66% of primary energy supply. It also faces natural disasters, climate shocks, physical constraints and high inequality. More than 17 million people still lack electricity and around 78 million lack clean cooking, especially in left-out rural, Caribbean and Indigenous communities. The real challenge is to make energy systems more inclusive, resilient and accessible. | I23: Energy Access And Affordability: Voluntary Action Plan For Latin America And The Caribbean | J23: This report from IDB and OLADE describes the challenges in reaching universal electricity access and recommends a series of voluntary actions. | K23: OLADE | L23: https://www.olade.org/en/publicaciones/energy-access-and-affordability-voluntary-action-plan-for-latin-america-and-the-caribbean/ | M23: 1321 | N23: Confirmed | O23: ✅
A24: 1.3.2 | F24: Latin America and the Caribbean has one of the world’s cleanest electricity matrices, with more than 60% of electricity generated from renewables, mainly hydropower. Yet the wider energy system remains heavily dependent on fossil fuels, especially in transport and industry. With growing renewable capacity and emerging green hydrogen pilots, the region can become a future green hydrogen hub if policy, finance and local innovation are aligned, while also using the transition to improve energy access and clean cooking solutions for marginalized communities. | G24: energy diversification | H24: Energy diversification refers to the strategy of using a variety of energy sources and technologies to meet energy needs, reducing dependence on a single source and enhancing energy security. | I24: Latin America Energy Outlook | J24: This report from the IEA discusses the energy outlook in Latin America, providing data and analysis on the diverse sources of renewable energy in the region. | K24: IEA | L24: https://iea.blob.core.windows.net/assets/1055131a-8dc4-488b-9e9e-7eb4f72bf7ad/LatinAmericaEnergyOutlook.pdf#%5B%7B%22num%22%3A645%2C%22gen%22%3A0%7D%2C%7B%22name%22%3A%22XYZ%22%7D%2C120.48%2C477.907%2C0%5D | M24: 1322 | N24: Confirmed | O24: ✅
A25: 1.3.2 | F25: With a well-designed financing and policy strategy, supported by strong institutional coordination, LAC can convert its abundant renewable potential into a just and resilient energy transition. Green bonds, blended finance, concessional loans, public funding to attract private investment, and redirected fossil-fuel subsidies can help expand clean energy, improve access for marginalized communities, and support clean cooking solutions. Linked with the region’s bioeconomy, e-mobility opportunities, and green hydrogen potential, such a transition can promote low-carbon industrialization, decent jobs, inclusion, and resilience. | G25: green jobs | H25: Green jobs are decent jobs that contribute to preserve or restore the environment, such as in renewable energy and energy efficiency. | I25: Measuring Green Jobs: A New Database for Latin America and Other Regions | J25: This policy paper analyzes the growth of green jobs in Latin America, where green jobs are defined as "increased demand," "enhanced skills," and "new and emerging" occupations | K25: World Bank | L25: https://documents1.worldbank.org/curated/en/099456306062431847/pdf/IDU-0c3127b0-7812-4cff-b0ce-5131c0460cdb.pdf | M25: 1323 | N25: Confirmed | O25: ✅
A26: 1.3.3 | B26: Africa | E26: Sustainable energy in Africa | F26: Africa’s energy landscape faces deep challenges but offers immense potential. The continent has significant renewable energy potential and critical minerals needed for clean energy technologies, positioning it as a key player in the global energy transition. | I26: Africa Energy Outlook 2022 | J26: This report provides a comprehensive overview of energy trends in Africa, with a section dedicated specifically to energy access. | K26: IEA | L26: https://www.iea.org/reports/africa-energy-outlook-2022 | M26: 1331 | N26: Updated | O26: World Energy Outlook 2025 (Africa Insights)
A27: 1.3.3 | F27: Although Africa has critical minerals and strong renewable and green hydrogen potential, local processing, value addition, and energy-related value chains remain limited. A just transition can convert these strengths into energy access, clean cooking, responsible mineral development, local industrialization, and green hydrogen opportunities. This would help break the cycle of limited access and limited development, while ensuring that African communities benefit directly. | G27: decentralized renewable energy systems | H27: Distributed renewable energy refers to systems that are relatively small and dispersed (such as small‑scale solar PV on rooftops) rather than large and centralized; or where generation and distribution occur independently from a centralized system. | I27: Energy Conversion and Management | M27: 1332 | N27: Updated
A28: 1.3.3 | F28: Africa can realize its energy opportunity through policy frameworks, investment, and delivery models that match the region’s renewable resource potential and development needs. Although Africa receives only a small share of global clean-energy investment, targeted finance can unlock renewable projects, energy-related value chains, skills development, and digitalization. With stronger policy and investment support, renewables could meet a large share of the region’s electricity needs by 2040, while off-grid systems, mini-grids, and decentralized renewable solutions can improve access and service quality in rural and underserved communities. | G28: nature-based solutions | H28: Nature-based solutions for energy resilience and efficiency refer to the use of natural systems such as green roofs, urban trees, natural shading and ecosystem restoration to reduce energy demand, improve cooling and strengthen climate resilience. When supported by long-term planning, they can also contribute to inclusive development. | I28: Catalogue of Nature-Based Solutions for Infrastructure Projects | J28: This presentation highlights several infrastructure opportunities for nature-based solutions in the energy sector. | K28: IFC | L28: https://www.ifc.org/content/dam/ifc/doc/2023/catalogue-of-nature-based-solutions-for-infrastructure-projects.pdf | M28: 1433 | N28: Confirmed | O28: ✅
A29: 1.3.4 | B29: Asia and the Pacific | E29: Sustainable energy in Asia Pacific | F29: Asia and the Pacific is a highly diverse and fast-changing region, with rapid urbanization, industrialization and economic growth driving future demand for energy, land, infrastructure and transport. The region also plays a major role in global clean-energy manufacturing, especially through China’s large share of solar PV production. Long-term planning is needed to reduce emissions, improve land use, strengthen infrastructure and support inclusive employment. Renewable energy systems and circular economy approaches are essential for meeting the region’s growth needs in a cleaner and more sustainable way. | G29: critical minerals for the energy transition | H29: Critical minerals for energy transition are essential raw materials, such as lithium, cobalt, and rare earth elements, that are necessary for the production of renewable energy technologies, batteries, and electric vehicles, playing a key role in reducing carbon emissions and facilitating the shift to sustainable energy systems. | I29: Resourcing the Energy Transition Principles to Guide Critical Energy Transition Minerals Towards Equity and Justice | J29: This UN report provides seven guiding principles on mining critical minerals for the energy transition | K29: UNSG | L29: https://www.un.org/sites/un2.un.org/files/report_sg_panel_on_critical_energy_transition_minerals_11_sept_2024.pdf | M29: 1333 | N29: Updated | O29: UN Guidance for Action on CETMs (June 2025)
A30: 1.3.4 | F30: Asia and the Pacific has made strong progress in energy access, but reliability remains a major challenge. Around 50 million people still lack reliable electricity access, while rural communities and Small Island Developing States face the deepest electricity and clean cooking gaps. At the same time, coal dependence keeps the region’s energy system carbon-intensive, with fossil-fuel-based electricity and heat generation accounting for around 53% of emissions. The region therefore needs stronger energy efficiency, grid restructuring and off-grid solutions to make energy access reliable and clean. | I30: ASEAN Sustainable Urbanization Report 2022 | J30: This report provides policy recommendations for sustainable growth in ASEAN cities, also briefly discussing increased energy demand | K30: ASEAN | L30: https://unhabitat.org/sites/default/files/2022/12/asean_sustainable_urbanisation_report_final_dec_2022.pdf | M30: 1341 | N30: Updated | O30: ASEAN & UN-Habitat Strategic Update (March 2024) ASEAN Sustainable Urbanisation Forum 2025 Insights
A31: 1.3.4 | F31: Asia and the Pacific’s energy transition must be planned as a wider economic and industrial transformation, not only as a shift in power generation. The region has a strong clean-energy manufacturing base, but this depends on secure mineral supply chains, efficient material use and sustainable product lifecycles. Lifecycle and circular economy approaches, including safe and green design, reduced material intensity, reuse, recycling and policy support for recovered materials, can reduce resource pressure. With regional cooperation, targeted finance, technology sharing and major efficiency gains, the region can move toward a reliable, affordable, inclusive and just energy system. | G31: integrated power markets | H31: Integrated power markets refer to interconnected electricity markets that allow for the seamless exchange of electricity across different regions or countries, promoting competition, efficiency, and reliability in energy supply. | I31: Green Jobs and a Just Transition for Climate Action in Asia and the Pacific | J31: This report outlines the potential for green jobs in the Asia region, including recommendations for how to transition informal workers to green industries | K31: ILO | L31: https://www.ilo.org/sites/default/files/wcmsp5/groups/public/%40asia/%40ro-bangkok/%40sro-bangkok/documents/publication/wcms_734887.pdf | M31: 1342 | N31: Confirmed | O31: ✅
A32: 1.3.4 | B32: Eastern Europe and Central Asia | E32: Sustainable energy in Eastern Europe and Central Asia | F32: Eastern Europe and Central Asia is facing a structural shift in its energy landscape due to climate impacts, war-related disruption, displacement, ageing infrastructure and EU candidacy pressures. Although the region has near-universal energy access, harsh winters make heating a life-saving necessity, while affordability remains a serious concern for vulnerable households. Heatwaves, droughts and water stress are adding pressure to electricity grids and energy infrastructure. Since heating remains largely hydrocarbon-intensive, the transition must prioritize cleaner, more efficient and affordable heating systems that protect people while reducing emissions. | G32: circular economy models | H32: Circular economy models are economic systems aimed at minimizing waste and making the most of resources by reusing, recycling, and regenerating materials, thereby creating a closed-loop system that reduces environmental impact. | I32: The Secrets to Unlocking the Next Frontier for a Circular Economy in the Asia-Pacific Region | J32: This report outlines six key drivers to unlocking circular economy across the Asia-Pacific region. | K32: UNESCAP | L32: https://www.unescap.org/sites/default/d8files/event-documents/ESCAP-2024-RP-secrets-unlocking-next-frontier-circular-economy.pdf | M32: 1343 | N32: Updated | O32: 2025 edition available: Jaipur Declaration on 3R and Circular Economy
A33: 1.3.5 | F33: Eastern Europe and Central Asia’s energy transition is shaped by resource strengths, fossil-fuel dependence and EU-integration pressures. Oil- and gas-exporting countries may have limited incentives to shift quickly to renewables, while hydropower still dominates despite strong solar and wind potential. Coal-rich countries need long-term plans to move from high-emission energy systems to cleaner alternatives. EU accession requires stronger power and gas interconnections, climate and energy plans, renewable targets and greenhouse gas reduction commitments. Carbon-border measures may pressure carbon-intensive exports but can also catalyse green hydrogen, clean industry, electric mobility and its critical-mineral-based opportunities. | G33: climate-resilient energy system | H33: A climate-resilient energy system is one that can adapt to and withstand the long-term changes in climate patterns and continue to operate under the immediate shocks from extreme weather events, and restore the system’s function after an interruption resulting from climate hazards. | I33: Modelling a Resilient and Integrated Energy System for Central Asia: a Roadmap for Regional interconnectivity | J33: This report models increased energy connectivity across Central Asia, a key lever for resilient energy systems. | K33: UNECE | L33: https://unece.org/sites/default/files/2025-03/Report.pdf | M33: 1351 | N33: Confirmed | O33: ✅
A34: 1.3.5 | F34: Eastern Europe and Central Asia’s transition depends on turning renewable-energy ambition, clean-fuel potential, responsible mineral development and targeted finance into practical implementation. Although climate action ambition remains insufficient in many countries, the growing role of renewables and the readiness to raise renewable-energy ambition create opportunities for UNDP to support energy policy development and pilot activities. Clean fuels, including hydrogen, can support future EU demand and local low-carbon transition, while mineral resources can create jobs and industrial opportunities if managed responsibly. With EU-integration support, SME and energy-efficiency programmes, international finance and private investment, the region can move toward a just, inclusive and low-carbon transition. | G34: energy poverty | H34: Energy Poverty is a lack of access to adequate, affordable, reliable, and high-quality energy services that are also environmentally friendly. This lack of access impacts various aspects of life, including lighting, cooking, heating, and overall economic development opportunities. | I34: Energy Policy | M34: 1352 | N34: Updated
A35: 1.4.1 | B35: Leveraging Cross-Cutting Approaches to Drive Systemic Change | C35: Approaches, Methods and Tools for Strategic Innovation | E35: Adopting varied approaches and tools to deliver the energy transition | F35: A whole-of-society approach integrates multiple stakeholders from all segments of society into policy planning, implementation, monitoring, and decision-making. It mitigates resistance and promotes inclusivity, shared responsibility, and systems thinking. | G35: SDG-Integrated Approaches | H35: SDG-integrated cross-cutting approaches for just energy transition refer to the use of whole-of-society, human rights-based, gender mainstreaming and intersectional approaches to design sustainable energy projects as wider transformational processes that support social, economic and environmental well-being. | I35: Hydropower Potential of the Central Asian Countries | J35: This data article surveys the hydropower potential of the five Central Asian countries: Kazakhstan, Kyrgyzstan, Tajikistan, Turkmenistan, and Uzbekistan. | K35: NUPI | L35: https://www.nupi.no/en/publications/cristin-pub/hydropower-potential-of-the-central-asian-countries | M35: 1353 | N35: Confirmed | O35: ✅
A36: 1.4.1 | F36: A human rights-based approach is aimed at safeguarding human rights within the development landscape. Deeply rooted in international human rights standards, it ensures equality, justice, and dignity for all by empowering individuals and communities to claim their rights. | G36: Whole-of-Society Approaches | H36: Whole-of-society approach in energy transition refers to the integration of diverse stakeholders from all segments of society into planning, implementation, monitoring and decision-making. It promotes inclusivity, shared responsibility, systems thinking and wider public acceptance of transition processes. | I36: Intersectionality Resource Guide and toolkit | J36: The “Intersectionality resource guide and toolkit”, a UN Women and United Nations Partnership on the Rights of Persons with Disabilities led collaborative initiative with support from United Nations and non-United Nations entities, aims to help both organizations and individual practitioners and experts to address intersectionality in policies and programmes. | K36: UNWOMEN | L36: https://www.unwomen.org/en/digital-library/publications/2022/01/intersectionality-resource-guide-and-toolkit | M36: 1311 | N36: Confirmed | O36: ✅
A37: 1.4.1 | F37: Gender mainstreaming approach advances gender equality by considering gender as an analytical variable throughout policy, programme, and project planning, implementation, monitoring, and evaluation. It helps identify gender disparities, address discriminatory practices, and ensure that policies and programmes benefit people of all genders equitably, in line with the UN Charter’s values of equality and inclusivity. | G37: Gender Mainstreaming and Intersectional Approaches | H37: Gender mainstreaming in energy transition refers to considering gender as an analytical variable throughout planning, implementation, monitoring and evaluation. It helps identify gender disparities, address discriminatory practices and ensure that policies and programmes benefit people of all genders equitably. Intersectional approach in energy transition refers to examining how overlapping social, economic and environmental factors shape access to clean energy and its impacts. It helps identify exclusionary policies, integrate marginalized voices and redistribute decision-making power in energy policy design. | I37: Gender Mainstreaming: A Global Strategy for Achieving Gender Equality and the Empowerment of Women and Girls | J37: This brief sets a strategy for gender mainstreaming at programmatic and institutional levels to achieve transformative gender results. | K37: UNWOMEN | L37: https://www.unwomen.org/en/digital-library/publications/2020/04/brochure-gender-mainstreaming-strategy-for-achieving-gender-equality-and-empowerment-of-women-girls | M37: 1312 | N37: Confirmed | O37: ✅
A38: 1.4.2 | B38: Addressing SDG7 Trade-offs for Sustainable Outcomes | E38: Africa‚Äôs energy transition is a transformative opportunity to address energy poverty, unlock green growth, and foster inclusive development. | F38: The rebound effect shows that increased access to affordable and reliable energy may unintentionally encourage wasteful water consumption and overexploitation of resources. To mitigate this risk, sustainable energy transition planning should integrate sufficiency, affordability mechanisms, and capacity-building. Sufficiency promotes efficient energy use without waste, affordability mechanisms make energy solutions financially accessible without encouraging overconsumption, and capacity-building educates communities on sustainable energy use and conservation. | G38: Rebound Effect and Mitigation Measures | H38: Rebound effect and mitigation measures refer to the risk that improved access to affordable and reliable energy may unintentionally increase resource use or overconsumption. Mitigation measures such as sufficiency, affordability mechanisms and capacity-building help ensure that expanded energy access supports sustainable use rather than wasteful consumption. | I38: Leaving No One Behind: Equality and Non-Discrimination at the Heart of Sustainable Development | J38: This publication sets out a conceptual framework that includes equality (the imperative of moving towards substantive equality of opportunity and outcomes for all groups), non-discrimination and the broader concept of equity. | K38: United Nations | L38: https://unsceb.org/sites/default/files/imported_files/CEB%20equality%20framework-A4-web-rev3.pdf | M38: 1313 | N38: Confirmed | O38: ✅
A39: 1.4.2 | F39: Sustainable energy expansion under SDG 7 can create land-use, water-security, and value-chain trade-offs. Bioenergy monocropping, large-scale solar projects, and hydropower may affect biodiversity, food security, agriculture, fishing livelihoods, and water systems. In addition, renewable energy technologies depend on critical minerals whose extraction, refining, and transport can involve water use, toxic effluents, and risks to aquatic ecosystems, aquifers, and geological stability. These risks require life-cycle assessment, integrated planning, and safeguards that protect ecosystems, livelihoods, and community rights. | G39: grid reliability | H39: Grid reliability refers to the ability of an electrical grid to consistently deliver electricity to consumers without interruptions or failures, central to resilience. | I39: Implementing the Water–Energy–Food–Ecosystems Nexus and Achieving the Sustainable Development Goals | J39: This publication compiles a number of case studies with the aim of highlighting the importance and benefits of the WEFE Nexus approach for development cooperation. It identifies pathways for a more integrated and sustainable use of resources that goes beyond traditional sector-specific development silos. | K39: UNESCO | L39: https://unesdoc.unesco.org/ark:/48223/pf0000379588 | M39: 1321 | N39: Confirmed | O39: ✅
A40: 1.4.2 | F40: Integrated planning, participatory decision-making, and context-specific solutions are essential to manage SDG 7 trade-offs. Innovative approaches such as bioenergy cultivation on degraded lands, agrivoltaics, life-cycle assessment of land and water impacts, coordinated water-energy planning, and reduced environmental footprints across the renewable energy value chain—from raw material extraction to infrastructure decommissioning—can help minimize negative impacts. Embedding socio-economic co-benefits into transition strategies ensures that renewable energy development enhances livelihoods, supports local enterprises, and promotes inclusive development outcomes. | G40: Innovation as a Safeguard for Managing SDG 7 Trade-offs | H40: Innovation as a safeguard for managing SDG 7 trade-offs refers to the use of practical and context-specific solutions to reduce the negative impacts of sustainable energy expansion. It includes approaches such as bioenergy cultivation on degraded lands, agrivoltaics, life-cycle assessment, coordinated water-energy planning and socio-economic co-benefits to make renewable energy development more balanced, resilient and inclusive. | I40: Integrating the Three Dimensions of Sustainable Development - A Frameworks & Tools | J40: This publication was produced to assist policymakers in addressing the question of how to achieve integration across the policy cycle and to assess levels of integration. This publication is a first step towards meeting the needs of policymakers for frameworks and tools to integrate the three dimensions of sustainable development. | K40: UNESCAP | L40: https://www.unescap.org/sites/default/files/Integrating%20the%20three%20dimensions%20of%20sustainable%20development%20A%20framework.pdf | M40: 1322 | N40: Confirmed | O40: ✅
...

Sheet Chapters
B1: module_id | C1: chapter_id | D1: title | E1: color | F1: description | G1: estimatedTime
A2: module | B2: 1 | D2: Intro to Sustainable Energy for Development | E2: #00C1FF | F2: Module 1 offers an overview of sustainable energy within the global development agenda, linking it to challenges like climate change and energy poverty, and opportunities for economic growth and energy security. It introduces SDG7, its progress, and interlinkages, while presenting UNDP’s Energy Moonshot and the Sustainable Energy Academy’s tools for accelerating energy transitions. | G2: 140 min
A3: module | B3: 2 | D3: Energy Access and Inclusive Energy Services | E3: #02A38A | F3: Module 2 explores energy access and inclusive energy services as fundamental human rights and essential to social progress, economic growth, and development. It addresses persistent global gaps—where 685 million lack access—and highlights how the sustainable energy transition can correct imbalances, improve lives, and deliver equitable, safe, and affordable energy for all. | G3: 160 min
A4: module | B4: 3 | D4: Just Energy Transition | E4: #59BA47 | F4: Module 3 explores the Just Energy Transition, emphasizing equity, justice, and inclusion in the shift to sustainable energy. It addresses social and environmental challenges, promotes locally tailored solutions, and highlights the need for community-led action, worker support, and economic diversification to ensure no one is left behind in the transition. | G4: 140 min
A5: module | B5: 4 | D5: Sustainable Energy Finance | E5: #FBC412 | F5: Module 4 explores financial and market strategies driving the global energy transition, especially in developing countries. It examines public-private investments, innovative financing, and market dynamics, while addressing barriers like regulatory hurdles and risks. It also emphasizes energy finance’s broader development impacts—including gender, social, governance, and environmental dimensions—and practical solutions for scaling investment. | G5: 200 min
A6: module | B6: 5 | D6: Energy Governance for a Just Energy Transition | E6: #E78625 | F6: Module 5 examines energy governance as a catalyst for a just energy transition, highlighting inclusive institutions, legal frameworks, civic engagement, and oversight. It introduces people-centered, adaptable, digital, and multi-level governance approaches, offering tools and case studies to enhance transparency, policy coherence, and accountability for equitable and sustainable energy transformation. | G6: 160 min
A7: module | B7: 6 | D7: The Climate Change-Energy Nexus | E7: #E05258 | F7: Module 6 explores the deep link between energy systems and climate change, emphasizing the urgent need to shift to zero-carbon energy. It addresses emissions, climate risks to infrastructure, and adaptive solutions like resilient grids and renewables—highlighting their transformative role in building climate resilience and securing a sustainable energy future. | G7: 160 min
A8: module | B8: 7 | D8: Data in Sustainable Energy | E8: #757AF0 | F8: Module 7 offers a in-depth introduction to the role of energy data in planning, monitoring, and evaluation for sustainable energy development. It emphasizes the importance of reliable, ethical data for achieving SDG7, explores standardized frameworks, key indicators, and challenges, and introduces innovative tools like AI and energy modeling for informed policymaking. | G8: 140 min
A9: module | B9: 8 | D9: Innovation in Sustainable Energy | E9: #1F5A95 | F9: Module 8 explores future energy trends and projections, emphasizing the creation of enabling environments for innovation. It highlights the role of partnerships, collaboration, and inclusive practices in driving sustainable energy transitions. Learners will gain tools to foster innovation ecosystems and lead transformative change across the global energy landscape. | G9: 100 min
A10: module | B10: 9 | D10: Derisking Renewable Energy Investments | E10: #006ab5 | F10: Module 9 introduces the UNDP’s Derisking Renewable Energy Investment (DREI) framework, which identifies key risks and barriers to renewable energy investment in developing countries. It covers both utility-scale and decentralised technologies, with a focus on Sub-Saharan Africa, and explains how risk affects project finance and cost of capital before outlining the DREI framework and its main stages. | G10: 90 min
A11: chapter | B11: 1 | C11: 1.1 | D11: Introduction to Energy Systems | F11: This chapter explores global energy flows, the energy trilemma, and the urgent need for a sustainable transition to meet climate and development goals. | G11: 30 min
A12: chapter | B12: 1 | C12: 1.2 | D12: Interlinkages between Energy and other SDGs | F12: This chapter explores SDG interlinkages, emphasizing integrated, context-specific energy solutions that maximize synergies, minimize trade-offs, and advance multiple development goals. | G12: 30 min
A13: chapter | B13: 1 | C13: 1.3 | D13: Approaches, Methods and Tools for Strategic Innovation | F13: This chapter describes approaches and methods currently being applied - within the UN system and beyond - to uncover system interconnections, policy coherence and strengthen integration across the SDGs. | G13: 30 min
A14: chapter | B14: 1 | C14: 1.4 | D14: Operationalizing Sustainable Energy Systems Transformation | F14: This chapter explores methods, approaches, and tools to operationalize the energy for development approach. | G14: 30 min
A15: chapter | B15: 2 | C15: 2.1 | D15: Understanding Energy Access: Concepts, Context, and Background | F15: This chapter explores energy access as a human right and a catalyst for unlocking development opportunities, examines energy poverty, and presents solutions to advance equitable, inclusive, and sustainable energy. | G15: 30 min
A16: chapter | B16: 2 | C16: 2.2 | D16: Current Status, Trends and Barriers to Energy Access | F16: This chapter analyzes global energy access disparities, highlighting barriers, trends, and solutions to improve access for underserved and marginalized populations. | G16: 30 min
A17: chapter | B17: 2 | C17: 2.3 | D17: Bridging the Energy Access Gap | F17: This chapter guides building energy systems centered on well-being, justice, and sustainability, emphasizing innovation, inclusivity, partnerships, and community-led solutions. | G17: 30 min
A18: chapter | B18: 3 | C18: 3.1 | D18: Introduction to the Energy Transition Landscape | F18: This chapter introduces the just energy transition, highlighting its social, gender, and ethical dimensions beyond decarbonization, and explores practical applications. | G18: 30 min
A19: chapter | B19: 3 | C19: 3.2 | D19: Ensuring a Just Transition for Workers and Affected Communities | F19: This chapter explores strategies to support workers and communities, ensuring equity, inclusion, and ethical practices in the sustainable energy transition. | G19: 30 min
A20: chapter | B20: 3 | C20: 3.3 | D20: A JET That Preserves Nature and Catalyze Ecnomic Growth | F20: This chapter examines the environmental impacts of the energy transition, highlighting the role of critical minerals and the need for sustainable, equitable practices. | G20: 30 min
A21: chapter | B21: 3 | C21: 3.4 | D21: Strategic Governance and Partnership Models for Just Energy Transitions | F21: This chapter highlights governance and partnerships as key to just transitions, emphasizing equity, foresight, inclusive planning, and innovative financing like JETPs. | G21: 30 min
A22: chapter | B22: 4 | C22: 4.1 | D22: Introduction to Sustainable Energy Finance and Market Dynamics | F22: This chapter explores sustainable energy finance, market dynamics, ESG factors, and investment challenges in aligning capital with global energy transition goals. | G22: 30 min
... A43: chapter | B43: 9 | C43: 9.3 | D43: Presentation of the DREI Framework | F43: This learning module introduces the DREI framework, guiding learners through its origins, key analytical components, and practical applications to assess risks, design public interventions, and support renewable energy investment planning. | G43: 30 min

Sheet Spellcheck - old
A1: lesson_id | B1: frame | C1: misspelled_word | D1: sentence
A2: 1.1.1 | B2: 5 | C2: indissociable | D2: The paradox of sustainable development lies on these two main elements that are indissociable from each other and critical to understand the most significant challenges of our times.
A3: 1.1.1 | B3: 8 | C3: visualizingenergy | D3: Sources: Our World in Data; United Nations Development Programme Boston University Institute for Global Sustainability | visualizingenergy.
A4: 1.1.1 | B4: 20 | C4: laregely | D4: Our current energy system is laregely failing the future.
A5: 1.1.2 | B5: 18 | C5: povertyhh | D5: While developed countries may see a 10% reduction in energy use due to efficiency improvements, energy demand in developing countries is projected to grow by over 25% because more people are getting lifted out of energy povertyhh.
A6: 1.2.0 | B6: 3 | C6: socieities | D6: Improving energy efficiency for building sustainable and resilient socieities
A7: 1.2.2 | B7: 18 | C7: socieities | D7: Improving energy efficiency for building sustainable and resilient socieities
A8: 1.3.2 | B8: 5 | C8: mln | D8: 78 mln
A9: 1.4.1 | B9: 15 | C9: porposes | D9: This report porposes a set of indicators to measure the gender gap in term of: access to electricity and clean cooking, employment and leadership, energy entrepreneurship, and the regulatory environment.
A10: 2.1.2 | B10: 47 | C10: satelite | D10: The World Bank data repository "Light Every Night" can be a useful data source for nighttime light satelite imagery.
A11: 2.2.0 | B11: 3 | C11: withtin | D11: Each part examines the unique challenges aand progress withtin these critical areas
A12: 2.2.0 | B12: 3 | C12: aand | D12: Each part examines the unique challenges aand progress withtin these critical areas
A13: 2.2.0 | B13: 3 | C13: distirbtuion | D13: This lesson explores the complex challenges obstructing equitable acccess to sustainable energy, highlighting issues in infrastructure and capacity, uneven distirbtuion of investments and the need for comprehensive measurement approaches.
... A76: 8.3.1 | B76: 12 | C76: notbaly | D76: Similar strategies are being explored notbaly in Africa through regional initiatives to develop battery and solar component industries closer to mineral sources.
