Workbook

Sheet Lessons
A1: Lesson Number | B1: Lesson Title | C1: Chapter Title | D1: Module Title | E1: Description | F1: Resource Number | G1: Key Concept | H1: Concept Definition | I1: Resource Title | J1: Resource Description | K1: Resource Link | L1: Resource Source | M1: Resource ID
A2: 1.1.1 | B2: The Great Energy Dilemma: Paradoxes of Sustainable Development | C2: Introduction to Energy Systems | D2: Intro to Sustainable Energy for Development | E2: Understanding the role of sustainable energy for human well-being and development | F2: 1 | G2: energy for development | H2: Energy for development refers to the provision and use of energy resources to support economic growth, improve living standards, and enhance social well-being in communities, particularly in developing regions. | I2: Energy and Development in a Changing World: A Framework for the 21st Century | J2: This framework reflects the global energy context of the 21st century, one that is marked by the numerous development gains and the related ever-increasing economic weight and energy demand of developing countries as they successfully fight poverty and move toward prosperity. | K2: Center on Global Energy Policy at COLUMBIA SIPA | L2: https://www.energypolicy.columbia.edu/publications/energy-and-development-changing-world-framework-21st-century/ | M2: 1111
A3: 1.1.1 | F3: 2 | G3: energy trilemma | H3: The energy trilemma refers to the challenge of balancing three key objectives in energy policy: ensuring energy security, promoting environmental sustainability, and providing energy equity or affordability for all consumers. | I3: Energy Development as a Driver of Economic Growth | J3: This chapter highlights the fact that the geometric increase in energy use in developing nations has significant effects. This chapter attempts to show the relationship between the rate of economic growth and energy consumption in developing nations. | K3: Wiley Online Library | L3: https://onlinelibrary.wiley.com/doi/abs/10.1002/9781119741503.ch5 | M3: 1112
A4: 1.1.1 | F4: 3 | G4: paris agreement goals | H4: The Paris Agreement goals refer to the international commitments made by countries to limit global warming to well below 2 degrees Celsius above pre-industrial levels, with efforts to limit the temperature increase to 1.5 degrees Celsius, and to enhance the ability to adapt to climate change impacts. | I4: Energy-Based Economic Development | J4: Energy-based economic development: How clean energy can drive development and stimulate economic growth delivers working definitions, common approaches, descriptions of supportive policy mechanisms, and suggested metrics for evaluation. | K4: ScienceDirect | L4: https://www.sciencedirect.com/science/article/abs/pii/S1364032110002583#:~:text=Energy%2Dbased%20economic%20development%20is,ways%20that%20contribute%20to%20job | M4: 1113
A5: 1.1.2 | B5: Energy as a Driver for Development | E5: Exploring the benefits of sustainable energy and examining the energy transition | F5: 1 | G5: nationally determined contributions | H5: Nationally Determined Contributions (NDCs) are the climate action plans that countries submit to outline their commitments to reduce greenhouse gas emissions and adapt to climate change, as part of the Paris Agreement. | I5: World Energy Outlook 2024 | J5: The 2024 edition of the IEA’s World Energy Outlook discusses the challenges of energy access, with 750 million people lacking electricity and over 2 billion without clean cooking fuels, predominantly in sub-Saharan Africa. The report also addresses the current trajectory of global energy transitions, warning of a potential rise of 2.4°C in global temperatures by 2100 if current policies persist. | K5: IEA | L5: https://www.iea.org/reports/world-energy-outlook-2024 | M5: 1121
A6: 1.1.2 | F6: 2 | G6: sustainable energy & renewable energy | H6: Sustainable energy refers to energy sources that are environmentally friendly and can be maintained over the long term without depleting resources or harming the ecosystem. Renewable energy is a subset of sustainable energy that comes from natural processes that are continuously replenished, such as solar, wind, and hydro power. | I6: Global Energy Perspective 2024 | J6: IRENA’s World Energy Transition Outlook highlights that the global energy transition is falling short, jeopardizing the achievement of the 1.5°C climate goal set at COP21 nearly a decade ago. While there is still time to act, an urgent course correction is essential to realign with this target. Achieving this requires addressing the structural and systemic barriers that continue to hinder progress in the energy transition. | K6: IRENA | L6: https://www.irena.org/Publications/2024/Nov/World-Energy-Transitions-Outlook-2024 | M6: 1122
A7: 1.1.2 | F7: 3 | G7: just energy transition | H7: A just energy transition refers to the shift from fossil fuels to renewable energy sources in a way that is fair and equitable, ensuring that all communities, especially those historically marginalized, benefit from the transition and are not left behind. | I7: World Energy Transitions Outlook 2024 | J7: The Global Energy Perspective 2024 provides a comprehensive demand outlook for 68 sectors and 78 fuels, aligned with a 1.5°C pathway under the Paris Agreement. It also introduces three updated bottom-up energy transition scenarios, redesigned to account for evolving global conditions such as geopolitical challenges, complex supply chains, and rising inflation. | K7: McKinsey & Company | L7: https://www.mckinsey.com/industries/energy-and-materials/our-insights/global-energy-perspective | M7: 1123
A8: 1.1.3 | B8: The Sustainable Energy Landscape | F8: 1
A9: 1.1.3 | F9: 2
A10: 1.1.3 | F10: 3
A11: 1.2.1 | B11: Access to electricity and clean cooking‚ÄØ(SDG 7.1) | C11: Interlinkages between Energy and Other SDGs | E11: Catalyzing progress across the SDGs through universal energy access | F11: 1 | G11: clean cooking | H11: Clean cooking refers to the use of safe, efficient, and environmentally friendly cooking technologies and fuels that reduce indoor air pollution and minimize health risks, while also lowering greenhouse gas emissions. | I11: 2024 Tracking SDG7 Report | J11: This annual report tracks global progress toward UN Sustainable Development Goal 7 and serves as a guide for policymakers and the international community in advancing energy access, energy efficiency, renewable energy and international cooperation. | K11: TRACKING SDG7 | L11: https://trackingsdg7.esmap.org/ | M11: 1211
A12: 1.2.1 | F12: 2 | G12: energy and health | H12: The relationship between energy consumption, production, and its impact on human health, including how energy systems affect air quality, access to clean water, and overall well-being. | I12: SDG7 Interactions | J12: The study provides an overview of interactions at the goal level between SDG7 – the ‘entry level goal’ for this assessment – and the other 16 SDGs. | K12: IIASA PURE | L12: https://pure.iiasa.ac.at/id/eprint/14621/1/SDGs-interactions-7-clean-energy.pdf | M12: 1212
A13: 1.2.1 | F13: 3 | G13: sdg synergies | H13: SDG synergies refer to the interconnected benefits and positive interactions that occur when efforts to achieve one Sustainable Development Goal (SDG) also support the achievement of other SDGs, leading to more effective and holistic progress in sustainable development. | I13: A Vision for Clean Cooking Access for All | J13: The report evidences that transforming the clean cooking landscape is a complex endeavour with no straight-forward solutions, but one that requires the establishment of clear policies and robust regulatory frameworks as foundational elements for attracting and driving investment in clean cooking projects. | K13: IEA | L13: https://www.iea.org/reports/a-vision-for-clean-cooking-access-for-all | M13: 1213
A14: 1.2.2 | B14: Renewable energy (SDG 7.2) | E14: Leveraging the SDG synergies and navigating the trade-offs in the energy transition | F14: 1 | G14: community rights in renewable energy | H14: Community rights in renewable energy refer to the legal and social entitlements of local communities to participate in, benefit from, and have a say in renewable energy projects that affect their environment and livelihoods. | I14: Addressing Energy’s Interlinkages with other SDGs | J14: This document was prepared in support of the review of the SDGs at the United Nations High-Level Political Forum 2022. This edition takes a closer look at interlinkages between energy and SDG 4 (education), SDG 5 (gender), and SDG 15 (life on land), identifying potential indicators that could help in tracking global progress in these interlinkages. | K14: United Nations | L14: https://sdgs.un.org/publications/report-2022-sdg7-tag-policy-briefs-addressing-energys-interlinkages-other-sdgs-47727 | M14: 1221
A15: 1.2.2 | F15: 2 | G15: energy value chain | H15: The energy value chain refers to the full range of processes involved in the production, distribution, and consumption of energy, including extraction, generation, transmission, and end-use. | I15: From goals to joules: A quantitative approach of interlinkages between energy and the Sustainable Development Goals | J15: This study aims to examine the complexity of the interconnections between energy and the SDGs, as well as give examples of how these linkages can be quantified. | K15: ScienceDirect | L15: https://www.sciencedirect.com/science/article/abs/pii/S2214629618308107 | M15: 1222
A16: 1.2.2 | F16: 3 | G16: water-energy-food nexus | H16: The water-energy-food nexus refers to the interconnectedness of water, energy, and food systems, highlighting how the management of one resource affects the others, and emphasizing the need for integrated approaches to ensure sustainability and security in these critical areas. | I16: Building a Nature-positive Energy Transformation - Why a Low-Carbon Economy is Better for People and Nature | J16: This report is builds on existing studies and quantifies and compares 30 environmental and socioeconomic impact metrics in two different energy scenarios for the future. It also presents a framework for establishing the nature-positive energy transformation that is essential to achieving critical climate and sustainable development goals. | K16: WWF | L16: https://wwf.panda.org/wwf_news/?9967866/Building-a-Nature-Positive-Energy-Transformation#:~:text=An%20energy%20system%20powered%20by,human%20health%2C%20biodiversity%20and%20ecosystems. | M16: 1223
A17: 1.2.3 | B17: Energy Efficiency (SDG 7.3) | E17: Improving energy efficiency for building sustainable and resilient socieities | F17: 1 | G17: energy and digitalization | H17: Energy and digitalization refers to the integration of digital technologies into the energy sector, enhancing efficiency, management, and innovation in energy production, distribution, and consumption. | I17: Energy efficiency and sustainable development goals (SDGs) | J17: This study attempts to connect Sustainable Development Goals (SDGs) with energy efficiency for 20 Asian and Pacific (AP) countries using Data Envelopment Analysis (DEA) from 2000 to 2018. | K17: ScienceDirect | L17: https://www.sciencedirect.com/topics/economics-econometrics-and-finance/sustainable-development-goals | M17: 1231
A18: 1.2.3 | F18: 2 | G18: energy efficiency | H18: Energy efficiency refers to using less energy to perform the same task or produce the same outcome, thereby reducing energy waste and lowering costs. | I18: Energy Efficiency 2024 | J18: Energy Efficiency 2024 is the IEA’s primary annual analysis on global energy efficiency developments, showing recent trends in energy intensity and demand, prices and policies. The report provides sector-specific analysis on buildings, appliances, industry and transport and explores system-wide themes such as electrification, flexibility, investment and employment. This report is launched in parallel with the new IEA Energy Efficiency Progress Tracker. | K18: IEA | L18: https://iea.blob.core.windows.net/assets/f304f2ba-e9a2-4e6d-b529-fb67cd13f646/EnergyEfficiency2024.pdf | M18: 1232
A19: 1.2.3 | F19: 3 | G19: waste-to-energy solutions | H19: Waste-to-energy solutions are processes that convert non-recyclable waste materials into usable forms of energy, typically electricity or heat, through methods such as combustion, gasification, or anaerobic digestion. | I19: From Efficiency to Sustainability: Examining the Paradox of Digitalization of Energy | J19: The study aims to analyze the implementations and benefits of digital technologies across various aspects of the energy industry. It specifically discusses the impact of the digitalization of energy on achieving Sustainable Development Goals, highlighting the benefits and challenges it can bring. | K19: SPRINGER NATURE LINK | L19: https://link.springer.com/chapter/10.1007/978-3-031-68427-2_1 | M19: 1233
A20: 1.3.1 | B20: Arab States | C20: Regions | E20: sustainable energy in the Arab states | F20: 1
A21: 1.3.1 | F21: 2
A22: 1.3.1 | F22: 3
A23: 1.3.2 | B23: Latin America and the Caribbean | E23: Sustainable energy in Latin America and the Caribbeans | F23: 1
A24: 1.3.2 | F24: 2
A25: 1.3.2 | F25: 3
A26: 1.3.3 | B26: Africa | E26: Sustainable energy in Africa | F26: 1
A27: 1.3.3 | F27: 2
A28: 1.3.3 | F28: 3
A29: 1.3.4 | B29: Asia and the Pacific | E29: Sustainable energy in Asia Pacific | F29: 1
A30: 1.3.4 | F30: 2
A31: 1.3.4 | F31: 3
A32: 1.3.5 | B32: Eastern Europe and Central Asia | E32: Sustainable energy in Eastern Europe and Central Asia | F32: 1
A33: 1.3.5 | F33: 2
A34: 1.3.5 | F34: 3
A35: 1.4.1 | B35: Leveraging Cross-Cutting Approaches to Drive Systemic Change | C35: Approaches, Methods and Tools for Strategic Innovation | D35: Operationalizing Sustainable Energy Systems Transformation | E35: Adopting varied approaches and tools to deliver the energy transition | F35: 1 | G35: critical minerals for energy transition | H35: Critical minerals for energy transition are essential raw materials, such as lithium, cobalt, and rare earth elements, that are necessary for the production of renewable energy technologies, batteries, and electric vehicles, playing a key role in reducing carbon emissions and facilitating the shift to sustainable energy systems. | I35: Intersectionality Resource Guide and toolkit | J35: The “Intersectionality resource guide and toolkit”, a UN Women and United Nations Partnership on the Rights of Persons with Disabilities led collaborative initiative with support from United Nations and non-United Nations entities, aims to help both organizations and individual practitioners and experts to address intersectionality in policies and programmes. | K35: UNWOMEN | L35: https://www.unwomen.org/en/digital-library/publications/2022/01/intersectionality-resource-guide-and-toolkit | M35: 1311
A36: 1.4.1 | F36: 2 | G36: energy diversification | H36: Energy diversification refers to the strategy of using a variety of energy sources and technologies to meet energy needs, reducing dependence on a single source and enhancing energy security. | I36: Gender Mainstreaming: A Global Strategy for Achieving Gender Equality and the Empowerment of Women and Girls | J36: This brief sets a strategy for gender mainstreaming at programmatic and institutional levels to achieve transformative gender results. | K36: UNWOMEN | L36: https://www.unwomen.org/en/digital-library/publications/2020/04/brochure-gender-mainstreaming-strategy-for-achieving-gender-equality-and-empowerment-of-women-girls | M36: 1312
A37: 1.4.1 | F37: 3 | G37: integrated power markets | H37: Integrated power markets refer to interconnected electricity markets that allow for the seamless exchange of electricity across different regions or countries, promoting competition, efficiency, and reliability in energy supply. | I37: Leaving No One Behind: Equality and Non-Discrimination at the Heart of Sustainable Development | J37: This publication sets out a conceptual framework that includes equality (the imperative of moving towards substantive equality of opportunity and outcomes for all groups), non-discrimination and the broader concept of equity. | K37: United Nations | L37: https://unsceb.org/sites/default/files/imported_files/CEB%20equality%20framework-A4-web-rev3.pdf | M37: 1313
A38: 1.4.2 | B38: Addressing SDG7 Trade-offs for Sustainable Outcomes | E38: Africa‚Äôs energy transition is a transformative opportunity to address energy poverty, unlock green growth, and foster inclusive development. | F38: 1 | G38: grid reliability | H38: Grid reliability refers to the ability of an electrical grid to consistently deliver electricity to consumers without interruptions or failures. | I38: Implementing the Water–Energy–Food–Ecosystems Nexus and Achieving the Sustainable Development Goals | J38: This publication compiles a number of case studies with the aim of highlighting the importance and benefits of the WEFE Nexus approach for development cooperation. It identifies pathways for a more integrated and sustainable use of resources that goes beyond traditional sector-specific development silos. | K38: UNESCO | L38: https://unesdoc.unesco.org/ark:/48223/pf0000379588 | M38: 1321
A39: 1.4.2 | F39: 2 | G39: low-carbon transport | H39: Low-carbon transport refers to transportation methods and systems that produce minimal greenhouse gas emissions, often through the use of renewable energy sources, electric vehicles, public transit, cycling, and walking. | I39: Integrating the Three Dimensions of Sustainable Development - A Frameworks & Tools | J39: This publication was produced to assist policymakers in addressing the question of how to achieve integration across the policy cycle and to assess levels of integration. This publication is a first step towards meeting the needs of policymakers for frameworks and tools to integrate the three dimensions of sustainable development. | K39: UNESCAP | L39: https://www.unescap.org/sites/default/files/Integrating%20the%20three%20dimensions%20of%20sustainable%20development%20A%20framework.pdf | M39: 1322
A40: 1.4.2 | F40: 3 | G40: sustainable heating | H40: Sustainable heating refers to methods of heating spaces that minimize environmental impact, often using renewable energy sources, energy efficiency practices, and low-carbon technologies. | I40: Life Cycle Assessment in Renewable Energy: Solar and Wind Perspectives | J40: The article underscores the significance of material selection in photovoltaic, solar, and wind systems, providing a critical overview of the current state of LCA research in renewable energy and stressing the need for standardized methodologies. | K40: MDPI | L40: https://www.mdpi.com/2076-3298/11/7/147 | M40: 1323
...

Sheet Chapters
A1: type | B1: module_id | C1: chapter_id | D1: title | E1: color | F1: description | G1: estimatedTime
A2: module | B2: 1 | D2: Intro to Sustainable Energy for Development | E2: #00C1FF | F2: Module 1 offers an overview of sustainable energy within the global development agenda, linking it to challenges like climate change and energy poverty, and opportunities for economic growth and energy security. It introduces SDG7, its progress, and interlinkages, while presenting UNDP’s Energy Moonshot and the Sustainable Energy Academy’s tools for accelerating energy transitions. | G2: 140 min
A3: module | B3: 2 | D3: Energy Access and Inclusive Energy Services | E3: #02A38A | F3: Module 2 explores energy access and inclusive energy services as fundamental human rights and essential to social progress, economic growth, and development. It addresses persistent global gaps—where 685 million lack access—and highlights how the sustainable energy transition can correct imbalances, improve lives, and deliver equitable, safe, and affordable energy for all. | G3: 160 min
A4: module | B4: 3 | D4: Just Energy Transition | E4: #59BA47 | F4: Module 3 explores the Just Energy Transition, emphasizing equity, justice, and inclusion in the shift to sustainable energy. It addresses social and environmental challenges, promotes locally tailored solutions, and highlights the need for community-led action, worker support, and economic diversification to ensure no one is left behind in the transition. | G4: 140 min
A5: module | B5: 4 | D5: Sustainable Energy Finance | E5: #FBC412 | F5: Module 4 explores financial and market strategies driving the global energy transition, especially in developing countries. It examines public-private investments, innovative financing, and market dynamics, while addressing barriers like regulatory hurdles and risks. It also emphasizes energy finance’s broader development impacts—including gender, social, governance, and environmental dimensions—and practical solutions for scaling investment. | G5: 200 min
A6: module | B6: 5 | D6: Energy Governance for a Just Energy Transition | E6: #E78625 | F6: Module 5 examines energy governance as a catalyst for a just energy transition, highlighting inclusive institutions, legal frameworks, civic engagement, and oversight. It introduces people-centered, adaptable, digital, and multi-level governance approaches, offering tools and case studies to enhance transparency, policy coherence, and accountability for equitable and sustainable energy transformation. | G6: 160 min
A7: module | B7: 6 | D7: The Climate Change-Energy Nexus | E7: #E05258 | F7: Module 6 explores the deep link between energy systems and climate change, emphasizing the urgent need to shift to zero-carbon energy. It addresses emissions, climate risks to infrastructure, and adaptive solutions like resilient grids and renewables—highlighting their transformative role in building climate resilience and securing a sustainable energy future. | G7: 160 min
A8: module | B8: 7 | D8: Data in Sustainable Energy | E8: #1F5A95 | F8: Module 7 offers a in-depth introduction to the role of energy data in planning, monitoring, and evaluation for sustainable energy development. It emphasizes the importance of reliable, ethical data for achieving SDG7, explores standardized frameworks, key indicators, and challenges, and introduces innovative tools like AI and energy modeling for informed policymaking. | G8: 140 min
A9: module | B9: 8 | D9: Innovation in Sustainable Energy | E9: #757AF0 | F9: Module 8 explores future energy trends and projections, emphasizing the creation of enabling environments for innovation. It highlights the role of partnerships, collaboration, and inclusive practices in driving sustainable energy transitions. Learners will gain tools to foster innovation ecosystems and lead transformative change across the global energy landscape. | G9: 100 min
A10: chapter | B10: 1 | C10: 1.1 | D10: Introduction to Energy Systems | F10: This chapter explores global energy flows, the energy trilemma, and the urgent need for a sustainable transition to meet climate and development goals. | G10: 30 min
A11: chapter | B11: 1 | C11: 1.2 | D11: Interlinkages between Energy and other SDGs | F11: This chapter explores SDG interlinkages, emphasizing integrated, context-specific energy solutions that maximize synergies, minimize trade-offs, and advance multiple development goals. | G11: 30 min
A12: chapter | B12: 1 | C12: 1.3 | D12: Approaches, Methods and Tools for Strategic Innovation | F12: This chapter describes approaches and methods currently being applied - within the UN system and beyond - to uncover system interconnections, policy coherence and strengthen integration across the SDGs. | G12: 30 min
A13: chapter | B13: 1 | C13: 1.4 | D13: Operationalizing Sustainable Energy Systems Transformation | F13: This chapter explores methods, approaches, and tools to operationalize the energy for development approach. | G13: 30 min
A14: chapter | B14: 2 | C14: 2.1 | D14: Topic Overview and Background | F14: This chapter explores energy access as a human right and a catalyst for unlocking development opportunities, examines energy poverty, and presents solutions to advance equitable, inclusive, and sustainable energy. | G14: 30 min
A15: chapter | B15: 2 | C15: 2.2 | D15: Current Status, Trends and Barriers to Energy Access | F15: This chapter analyzes global energy access disparities, highlighting barriers, trends, and solutions to improve access for underserved and marginalized populations. | G15: 30 min
A16: chapter | B16: 2 | C16: 2.3 | D16: Bridging the Energy Access Gap | F16: This chapter guides building energy systems centered on well-being, justice, and sustainability, emphasizing innovation, inclusivity, partnerships, and community-led solutions. | G16: 30 min
A17: chapter | B17: 3 | C17: 3.1 | D17: Introduction to the Energy Transition Landscape | F17: This chapter introduces the just energy transition, highlighting its social, gender, and ethical dimensions beyond decarbonization, and explores practical applications. | G17: 30 min
A18: chapter | B18: 3 | C18: 3.2 | D18: Ensuring a Just Transition for Workers and Affected Communities | F18: This chapter explores strategies to support workers and communities, ensuring equity, inclusion, and ethical practices in the sustainable energy transition. | G18: 30 min
A19: chapter | B19: 3 | C19: 3.3 | D19: A JET That Preserves Nature and Catalyze Ecnomic Growth | F19: This chapter examines the environmental impacts of the energy transition, highlighting the role of critical minerals and the need for sustainable, equitable practices. | G19: 30 min
A20: chapter | B20: 3 | C20: 3.4 | D20: Strategic Governance and Partnership Models for Just Energy Transitions | F20: This chapter highlights governance and partnerships as key to just transitions, emphasizing equity, foresight, inclusive planning, and innovative financing like JETPs. | G20: 30 min
A21: chapter | B21: 4 | C21: 4.1 | D21: Introduction to Sustainable Energy Finance and Market Dynamics | F21: This chapter explores sustainable energy finance, market dynamics, ESG factors, and investment challenges in aligning capital with global energy transition goals. | G21: 30 min
... A40: chapter | B40: 8 | C40: 8.3 | D40: Partnerships for Collaboration and Development | F40: This chapter explores some innovations—decentralized systems, energy storage, and circular economy—that enhance resilience, access, and sustainability in the energy transition. | G40: 30 min

Sheet Sheet1
A1: Module | B1: Content | C1: Case Studies | D1: Graphics (Content) | E1: Graphics (Design) | F1: Charts | G1: Maps
A2: 1 | B2: Zayna | C2: Alfred | D2: Alfred | E2: Anja | F2: Alfred | G2: Frederick
A3: 2 | B3: Shade | C3: Alfred | D3: Alfred | E3: Anja | F3: Gabriela & Alfred | G3: Frederick
A4: 3 | B4: Danae | C4: (Hiring OV) | D4: Julie | E4: Dorothee | F4: Gabriela | G4: Frederick
A5: 4 | B5: Adam | C5: (Hiring OV) | D5: Booma | E5: Arukhan | F5: Divya & Zhong | G5: Frederick
A6: 5 | B6: Farida | C6: (Hiring OV) | D6: Francis | E6: Lidan | G6: Frederick
A7: 6 | B7: Zayna | C7: Ahmad | D7: Ahmad | E7: Lidan | F7: Ahmad | G7: Frederick
A8: 7 | B8: Danae | C8: Ahmad | D8: Ahmad | E8: Arukhan | F8: Ahmad | G8: Frederick
A9: 8 | B9: Shade & Farida | C9: (Hiring OV) | D9: (Hiring OV) | E9: Dorothee | G9: Frederick

Sheet ToC-old
A1: Number | B1: Lesson Title | C1: Overview | D1: Chapter Title | E1: Module Title | F1: Key Concept 1 | G1: Key Concept 2 | H1: Key Concept 3 | I1: Key Concept 4
A2: 1.1.1 | B2: Introduction to the Energy for Development pathway | C2: Understanding the role of sustainable energy for human well-being and development | D2: Introduction to Energy Systems | E2: Intro to Sustainable Energy for Development | F2: Energy for Development | G2: Energy Trilemma | H2: Paris Agreement Goals | I2: Primary Energy & Total Final Energy Consumption
A3: 1.1.2 | B3: The Sustainable Energy Landscape | C3: Exploring the benefits of sustainable energy and examining the energy transition | F3: Sustainable Energy & Renewable Energy | G3: Nationally Determined Contributions | H3: Just Energy Transition
A4: 1.1.3 | B4: The Path to Achieving Universal Energy Access by 2030 | C4: Discusses comprehensive strategies to expand universal energy access, focusing on scalable solutions for electricity, clean cooking, and sustainable transportation in emerging markets. It addresses both technological and financing challenges while assessing current progress and gaps. | F4: SDG7 Targets
A5: 1.1.4 | B5: Financing the Sustainable Energy Revolution | C5: Focusing on the finance landscape and highlighting the gap
A6: 1.2.1 | B6: Access to electricity and clean cooking (SDG 7.1) | C6: Catalyzing progress across the SDGs through universal energy access | D6: Interlinkages between Energy and Other SDGs | F6: SDG Synergies | G6: Clean Cooking | H6: Energy and Health
A7: 1.2.2 | B7: Renewable energy (SDG 7.2) | C7: Leveraging the SDG synergies and navigating the trade-offs in the energy transition | F7: Water-Energy-Food Nexus | G7: Energy Value Chain | H7: Community Rights in Renewable Energy
A8: 1.2.3 | B8: Energy Efficiency (SDG 7.3) | C8: Improving energy efficiency for building sustainable and resilient socieities | F8: Energy Efficiency | G8: Waste-to-Energy Solutions | H8: Energy and Digitalization
A9: 1.2.4 | B9: Integrated Approach | C9: Adopting varied approaches and tools to deliver the energy transition | D9: Approaches, Methods and Tools for Strategic Innovation | F9: Systems Thinking | G9: Gender Mainstreaming | H9: Intersectionality
A10: 1.3.1 | B10: Latin America and the Caribbean | C10: Known for its renewable energy potential, the region faces inequality and biodiversity challenges. | D10: Regional Perspective | F10: Energy Diversification | G10: Integrated Power Markets | H10: Critical Minerals for Energy Transition
A11: 1.3.2 | B11: Eastern Europe and Central Asia | C11: This fossil fuel-reliant region has untapped renewable energy potential. | F11: Grid Reliability | G11: Sustainable Heating | H11: Low-carbon Transport
A12: 1.3.3 | B12: Arab States | C12: Sustainable energy is central to human security and socioeconomic progress in the Arab States. | F12: Energy Resilience | G12: Social Protection | H12: Energy Services in Displacement Settings
A13: 1.3.4 | B13: Asia-Pacific | C13: Home to rapid economic growth and diverse challenges, Asia-Pacific's energy transition is critical to achieving global net-zero goals. | F13: Green Growth | G13: Sustainable Urbanization | H13: Sustainable Cooling
A14: 1.3.5 | B14: Africa | C14: Africa’s energy transition is a transformative opportunity to address energy poverty, unlock green growth, and foster inclusive development. | F14: Energy Poverty | G14: Productive Use of Energy | H14: Africa Minigrids Program
A15: 1.4.1 | B15: The Sustainable Energy Academy: Modules 2-8 | C15: Learning the vision of the Sustainable Energy Academy | D15: The Sustainable Energy Academy | F15: The UNDP Sustainable Energy Hub | G15: Energy Moonshot
A17: Module 2
A18: 2.1.1 | B18: Energy Access - Core Concepts | C18: This lesson focuses on global perspective on energy access and on the link between energy access and poverty alleviation. It also covers the nuances between energy access and inclusive energy services, and the types of energy uses and applications | D18: Topic Overview and Background | E18: Energy Access and Inclusive Energy Services | F18: Energy Access | G18: Inclusive Energy Services | H18: Fundamental Energy Needs
A19: 2.1.2 | B19: Sustainable Energy to power development | C19: This lesson focuses on the critical requirements to ensure sustainable energy access, including the building blocks of sustainable energy access | F19: Sustainable Energy Access | G19: energy and development economics
A20: 2.1.3 | B20: Energy Poverty and Fuel Poverty | C20: This lesson covers the reality of energy poverty, its causes and impacts, and the tools to measure the challenge of addressing this issue | F20: Energy Poverty | G20: Fuel Poverty
A21: 2.2.1 | B21: The Energy Access Landscape | C21: This lesson provides an overview of the key characteristics and statistics of the disparities in access to energy services | D21: Current Status, Trends and Barriers to Energy Access | F21: Global Energy Gap | G21: energy access for informal settlements | H21: energy in crisis settings
A22: 2.2.2 | B22: Status and Trends | C22: This lesson focuses on current status and trends on the global energy gap including access to fundamental energy needs: electricity, clean cooking, heating and cooling. Each part examines the unique challenges aand progress withtin these critical areas | F22: Access to Clean Cooking | G22: heating and cooling fuels and technologies
A23: 2.2.3 | B23: Challenges for universal energy access | C23: This lesson explores the complex challenges obstructing equitable acccess to sustainable energy, highlighting issues in infrastructure and capacity, uneven distirbtuion of investments and the need for comprehensive measurement approaches. | F23: financial de-risking strategies | G23: energy affordability
A24: 2.3.1 | B24: An Intersectional Approach | C24: This lesson explores how an intersectional approach can transform energy access by addressing the overlapping identities that shape people's experience and challenges. The lesson presents practical strategies to operationalize intersectionality in sustainable energy acces sprogramming. | D24: Bridging the Energy Access Gap | F24: Intersectionality | G24: Inclusive and sustainable energy access
A25: 2.3.2 | B25: Technological Solutions | C25: The lesson highlights the key technological solutions that can accelerate the path towards universal energy access while supporting the transition to clean energy. | F25: Off-grid renewable energy systems | G25: Solar home systems | H25: Mini-grids | I25: E-cooking
A26: 2.3.3 | B26: Financing Mechanisms | C26: This lesson explains how financing mechanisms can incentivize energy access and inclusive energy services with a focus on underserved and vulnerable communities. | F26: Result-based financing models | G26: Pay as you go models | H26: Microfinancing
A27: 2.3.4 | B27: Policy Frameworks | C27: This lesson explores three policy instruments: subsidies, tax incentives and regulatory reforms, and how they contribute to the promotion of sustainable energy solutions. | F27: energy subsidies | G27: fossil fuel subsidies
A28: 2.3.5 | B28: Collaborative Multi-Stakeholder Partnerships | C28: This lesson explores the importance of multi-stakeholder partnerships and the role of international organizations, NGOs, development agencies, the private sector and local communities in advancing energy access objectives, as well as the associated challenges and conflicts. | F28: multi-stakeholder partnership | G28: Community Empowerment | H28: Participatory Diagnosis, Design, Monitoring, and Evaluation
A29: Module 3
A30: 3.1.1 | B30: The Energy Transition In Context | C30: This lesson will explore how a just transition is about more than just technical solutions or policy frameworks; it is about addressing deep-rooted socio-economic disparities, fostering participatory governance, and empowering all stakeholders to engage in the transition process. | D30: Introduction to the Energy Transition Landscape | E30: Just Energy Transition | F30: Energy Transition | G30: Net Zero | H30: Carbon Neutrality
A31: 3.1.2 | B31: Unpacking The Concept Of A Just Energy Transition | C31: This lesson outlines the just energy transition, focusing on fairness, equity, and inclusivity in sustainable energy shifts. Originating from labor rights, it addresses historical inequities through environmental, climate, and energy justice. It highlights localized solutions and global frameworks like the AJET principles to balance urgent climate action with social and economic justice. | F31: Just Energy Transition
A32: 3.1.3 | B32: Key Challenges In The Global South | C32: This lesson delves into the specific challenges and opportunities that developing countries face in the context of the just energy transition. By examining these dynamics, we aim to shed light on strategies and initiatives that can facilitate a transition towards a more sustainable and equitable energy future for all. | F32: Localized Solutions | G32: Energy Equity | H32: Energy Poverty
A33: 3.2.1 | B33: Human rights and socio-economic impacts | C33: This lesson addresses human rights and socio-economic challenges in renewable energy transitions, including land displacement, labor rights abuses in mineral extraction, and inequitable benefits. It emphasizes inclusive policies, the Escazú Agreement for environmental democracy, and participatory processes like FPIC to protect indigenous rights and ensure equity. | D33: Ensuring a Just Transition for Workers and Affected Communities | F33: Inclusive Policy Frameworks | G33: Free, Prior, and Informed Consent (FPIC)
A34: 3.2.2 | B34: Worker Retraining and Employment Disparities | C34: This lesson focuses on worker retraining and skills development for renewable energy transitions, emphasizing policies to address job displacement, regional disparities, and gender gaps. | F34: Just Transition Workforce Programs | G34: Gender Gap in Energy Employment | H34: Skills Development Ecosystems
A35: 3.2.3 | B35: Social Safety Nets and Income Support | C35: This lesson focuses on social safety nets and income support in energy transitions, emphasizing measures like Energy Safety Nets (ESNs) to prevent energy poverty and ensure affordability for vulnerable groups. It highlights targeted subsidies to reduce inequalities, gender-sensitive policies for inclusive access, and the role of these programs in poverty reduction and social stability during shifts to sustainable energy. | F35: Energy Safety Nets (ESNs) | G35: Targeted Energy Subsidies | H35: Gender-sensitive Measures
A36: 3.2.4 | B36: Community-led sustainable energy projects and community-based solutions | C36: This lesson explores community-led sustainable energy projects as key drivers of equitable transitions, empowering local communities through renewable energy adoption. It emphasizes social cohesion, economic development, and environmental stewardship via grassroots initiatives, supported by policy reforms and global best practices. Highlighting frameworks like the IEA’s People-Centered Clean Energy Transitions Programme, it underscores energy democracy and inclusive solutions to ensure equitable access and resilience in shifting energy systems. | F36: Energy Communities | G36: Energy Democracy | H36: Social Cohesion
A37: 3.3.1 | B37: Critical Minerals and Materials | C37: This lesson addresses critical minerals essential for renewable energy technologies, highlighting challenges like rising demand, geographic concentration, and environmental/social impacts. It emphasizes the need for responsible extraction practices to bridge gaps between policies and on-ground outcomes. While offering economic opportunities for resource-rich nations, it underscores risks of resource mismanagement and calls for international cooperation to ensure equitable governance, sustainable development, and a just energy transition. | D37: A JET that Preserves Nature and Catalyzes Economic Growth | F37: Critical Minerals | G37: Sustainable Supply Chains | H37: Responsible Extraction Practices
A38: 3.3.2 | B38: Environmental Concerns of Clean Energy Technology Deployment | C38: This lesson examines environmental concerns of renewable energy technologies like wind, solar, and hydropower, highlighting challenges such as land use, habitat disruption, water consumption, and hazardous materials. While lifecycle assessments show renewables have significantly lower GHG emissions than fossil fuels, the lesson stresses the need for mitigation strategies (e.g., turbine placement, solar panel recycling, habitat protection) to minimize ecological impacts and ensure sustainable deployment. | F38: Lifecycle Assessment (LCA) | G38: Habitat Fragmentation Mitigation | H38: Renewable Technology Recycling
A39: 3.3.3 | B39: Advancing the Value Chain | C39: This lesson examines advancing the value chain in critical minerals and battery production, emphasizing opportunities for developing nations to shift from raw material exports to high-value processing. It highlights regional collaboration, vertical integration, and sustainable practices (e.g., recycling) to address socio-environmental impacts. Strategic governance and public-private partnerships are underscored as key drivers for economic resilience and equitable growth in the global energy transition. | F39: Value Chain | G39: High-value Processing Localization | H39: Circular Economy Models
A40: 3.4.1 | B40: Governance Strategies for a Just Energy Transition | C40: This lesson explores key energy governance strategies employed by UNDP, introduces the concept of energy democracy, and highlights practical examples. | D40: Strategic Governance and Partnership Models for Just Energy Transitions | F40: Energy Policy Frameworks | G40: Multi-level Governance | H40: Participatory Decision-making
A41: 3.4.2 | B41: Importance of Proactive Planning and Strategic Foresight | C41: This lesson underscores the importance of proactive planning and strategic foresight in navigating the energy transition amid global crises like cost-of-living pressures and geopolitical instability. It highlights the need for collaborative governance and equitable infrastructure transformation to address historical inequities and build resilient systems | F41: Strategic Foresight | G41: Collaborative Governance
...

Sheet Glossary-old
A1: Term | B1: Lesson | C1: Lesson Title | D1: Definition
A2: energy for development | B2: 1.1.1 | C2: Introduction to the Energy for Development pathway | D2: Energy for development refers to the provision and use of energy resources to support economic growth, improve living standards, and enhance social well-being in communities, particularly in developing regions.
A3: energy trilemma | B3: 1.1.1 | C3: Introduction to the Energy for Development pathway | D3: The energy trilemma refers to the challenge of balancing three key objectives in energy policy: ensuring energy security, promoting environmental sustainability, and providing energy equity or affordability for all consumers.
A4: paris agreement goals | B4: 1.1.1 | C4: Introduction to the Energy for Development pathway | D4: The Paris Agreement goals refer to the international commitments made by countries to limit global warming to well below 2 degrees Celsius above pre-industrial levels, with efforts to limit the temperature increase to 1.5 degrees Celsius, and to enhance the ability to adapt to climate change impacts.
A5: primary energy & total final energy consumption | B5: 1.1.1 | C5: Introduction to the Energy for Development pathway | D5: Primary energy refers to the energy found in nature that has not been subjected to any conversion or transformation processes, such as fossil fuels, solar energy, and wind energy. Total final energy consumption is the total amount of energy consumed by end-users, including households, industries, and transportation, after accounting for energy losses during conversion and distribution.
A6: nationally determined contributions | B6: 1.1.2 | C6: The Sustainable Energy Landscape | D6: Nationally Determined Contributions (NDCs) are the climate action plans that countries submit to outline their commitments to reduce greenhouse gas emissions and adapt to climate change, as part of the Paris Agreement.
A7: sustainable energy & renewable energy | B7: 1.1.2 | C7: The Sustainable Energy Landscape | D7: Sustainable energy refers to energy sources that are environmentally friendly and can be maintained over the long term without depleting resources or harming the ecosystem. Renewable energy is a subset of sustainable energy that comes from natural processes that are continuously replenished, such as solar, wind, and hydro power.
A8: just energy transition | B8: 1.1.2 | C8: Introduction to Energy Governance, The Sustainable Energy Landscape, Unpacking The Concept Of A Just Energy Transition | D8: A just energy transition refers to the shift from fossil fuels to renewable energy sources in a way that is fair and equitable, ensuring that all communities, especially those historically marginalized, benefit from the transition and are not left behind.
A9: sdg7 targets | B9: 1.1.3 | C9: The Path to Achieving Universal Energy Access by 2030 | D9: SDG 7 targets refer to the specific goals outlined under the United Nations Sustainable Development Goal 7, which aims to ensure access to affordable, reliable, sustainable, and modern energy for all by 2030. These targets include increasing the share of renewable energy, improving energy efficiency, and enhancing international cooperation to facilitate access to clean energy.
A10: clean cooking | B10: 1.2.1 | C10: Access to electricity and clean cooking_(SDG 7.1) | D10: Clean cooking refers to the use of safe, efficient, and environmentally friendly cooking technologies and fuels that reduce indoor air pollution and minimize health risks, while also lowering greenhouse gas emissions.
A11: energy and health | B11: 1.2.1 | C11: Access to electricity and clean cooking_(SDG 7.1) | D11: The relationship between energy consumption, production, and its impact on human health, including how energy systems affect air quality, access to clean water, and overall well-being.
A12: sdg synergies | B12: 1.2.1 | C12: Access to electricity and clean cooking_(SDG 7.1) | D12: SDG synergies refer to the interconnected benefits and positive interactions that occur when efforts to achieve one Sustainable Development Goal (SDG) also support the achievement of other SDGs, leading to more effective and holistic progress in sustainable development.
... A240: deep learning | B240: 7.4.2 | C240: Emerging Trends and Technologies in Energy | D240: Deep learning is a subset of machine learning that uses neural networks with many layers to analyze and learn from large amounts of data, enabling tasks like image and speech recognition.
A241: action opportunities | D241: Action opportunities refer to specific chances or options available for individuals, organizations, or communities to take meaningful steps towards achieving sustainability goals or improving energy efficiency.
A242: africa minigrids project | D242: The Africa Minigrids Project is an initiative aimed at expanding access to electricity in rural and underserved areas of Africa through the development and implementation of small-scale, decentralized energy systems, known as minigrids, which can operate independently or in conjunction with the main power grid.
A243: ai for smart grid optimization | D243: AI for smart grid optimization refers to the use of artificial intelligence technologies to enhance the efficiency, reliability, and management of electrical grids by analyzing data, predicting demand, and optimizing energy distribution.
A244: appropriate and independent oversight | D244: A system of monitoring and evaluation that ensures decisions and actions are made transparently and accountably, without undue influence from those being overseen.
A245: benefit-sharing agreements | D245: Benefit-sharing agreements are arrangements that ensure that the benefits derived from the use of natural resources, particularly genetic resources, are shared fairly and equitably with the communities or countries that provide them.
A246: biochar | D246: Biochar is a stable, carbon-rich material produced by pyrolyzing organic matter, such as plant biomass, in a low-oxygen environment, and is used to improve soil health and sequester carbon.
A247: biodigestion | D247: Biodigestion is a biological process that breaks down organic materials, such as food waste and manure, in the absence of oxygen, producing biogas (a mixture of methane and carbon dioxide) and digestate (a nutrient-rich residue).
A248: biofuels | D248: Biofuels are renewable energy sources made from organic materials, such as plants and animal waste, that can be used to produce heat, electricity, or power vehicles.
A249: biomass | D249: Biomass refers to organic material, such as plants and animal waste, that can be used as a renewable energy source through processes like combustion or conversion into biofuels.
A250: blockchain for energy trading | D250: Blockchain for energy trading refers to the use of blockchain technology to facilitate, record, and verify transactions in the buying and selling of energy, enabling decentralized and transparent energy markets.
A251: blue carbon | D251: Blue carbon refers to the carbon captured and stored by coastal and marine ecosystems, such as mangroves, salt marshes, and seagrasses, which play a crucial role in mitigating climate change by sequestering carbon dioxide from the atmosphere.
A252: blue economy | D252: The blue economy refers to the sustainable use of ocean resources for economic growth, improved livelihoods, and jobs while preserving the health of ocean ecosystems.
... A387: women's economic empowerment | D387: Women's economic empowerment refers to the process of enabling women to have equal access to economic resources, opportunities, and decision-making power, allowing them to participate fully in the economy and improve their financial independence and well-being.

Sheet Resources-old
A1: Lesson | B1: Lesson Title | C1: Resource # | D1: Title | E1: Description (60 words max) | F1: Source | G1: Link
A2: 1.1.1 | B2: ENERGY AS A DRIVER FOR SUSTAINABLE DEVELOPMENT | C2: 1 | D2: Energy and Development in a Changing World: A Framework for the 21st Century | E2: This framework reflects the global energy context of the 21st century, one that is marked by the numerous development gains and the related ever-increasing economic weight and energy demand of developing countries as they successfully fight poverty and move toward prosperity. | F2: Center on Global Energy Policy at COLUMBIA SIPA | G2: https://www.energypolicy.columbia.edu/publications/energy-and-development-changing-world-framework-21st-century/
A3: 1.1.1 | C3: 2 | D3: Energy Development as a Driver of Economic Growth | E3: This chapter highlights the fact that the geometric increase in energy use in developing nations has significant effects. This chapter attempts to show the relationship between the rate of economic growth and energy consumption in developing nations. | F3: Wiley Online Library | G3: https://onlinelibrary.wiley.com/doi/abs/10.1002/9781119741503.ch5
A4: 1.1.1 | C4: 3 | D4: Energy-Based Economic Development | E4: Energy-based economic development: How clean energy can drive development and stimulate economic growth delivers working definitions, common approaches, descriptions of supportive policy mechanisms, and suggested metrics for evaluation. | F4: ScienceDirect | G4: https://www.sciencedirect.com/science/article/abs/pii/S1364032110002583#:~:text=Energy%2Dbased%20economic%20development%20is,ways%20that%20contribute%20to%20job
A5: 1.1.2 | B5: SUSTAINABLE ENERGY LANDSCAPE | C5: 1 | D5: World Energy Outlook 2024 | E5: The 2024 edition of the IEA’s World Energy Outlook discusses the challenges of energy access, with 750 million people lacking electricity and over 2 billion without clean cooking fuels, predominantly in sub-Saharan Africa. The report also addresses the current trajectory of global energy transitions, warning of a potential rise of 2.4°C in global temperatures by 2100 if current policies persist. | F5: IEA | G5: https://www.iea.org/reports/world-energy-outlook-2024
A6: 1.1.2 | C6: 2 | D6: Global Energy Perspective 2024 | E6: IRENA’s World Energy Transition Outlook highlights that the global energy transition is falling short, jeopardizing the achievement of the 1.5°C climate goal set at COP21 nearly a decade ago. While there is still time to act, an urgent course correction is essential to realign with this target. Achieving this requires addressing the structural and systemic barriers that continue to hinder progress in the energy transition. | F6: IRENA | G6: https://www.irena.org/Publications/2024/Nov/World-Energy-Transitions-Outlook-2024
A7: 1.1.2 | C7: 3 | D7: World Energy Transitions Outlook 2024 | E7: The Global Energy Perspective 2024 provides a comprehensive demand outlook for 68 sectors and 78 fuels, aligned with a 1.5°C pathway under the Paris Agreement. It also introduces three updated bottom-up energy transition scenarios, redesigned to account for evolving global conditions such as geopolitical challenges, complex supply chains, and rising inflation. | F7: McKinsey & Company | G7: https://www.mckinsey.com/industries/energy-and-materials/our-insights/global-energy-perspective
A8: 1.2.1 | B8: =VLOOKUP(A8,'ToC-old'!A:B,2,FALSE) -> Access to electricity and clean cooking (SDG 7.1) | C8: 1 | D8: 2024 Tracking SDG7 Report | E8: This annual report tracks global progress toward UN Sustainable Development Goal 7 and serves as a guide for policymakers and the international community in advancing energy access, energy efficiency, renewable energy and international cooperation. | F8: TRACKING SDG7 | G8: https://trackingsdg7.esmap.org/
A9: 1.2.1 | C9: 2 | D9: SDG7 Interactions | E9: The study provides an overview of interactions at the goal level between SDG7 – the ‘entry level goal’ for this assessment – and the other 16 SDGs. | F9: IIASA PURE | G9: https://pure.iiasa.ac.at/id/eprint/14621/1/SDGs-interactions-7-clean-energy.pdf
A10: 1.2.1 | C10: 3 | D10: A Vision for Clean Cooking Access for All | E10: The report evidences that transforming the clean cooking landscape is a complex endeavour with no straight-forward solutions, but one that requires the establishment of clear policies and robust regulatory frameworks as foundational elements for attracting and driving investment in clean cooking projects. | F10: IEA | G10: https://www.iea.org/reports/a-vision-for-clean-cooking-access-for-all
A11: 1.2.2 | B11: =VLOOKUP(A11,'ToC-old'!A:B,2,FALSE) -> Renewable energy (SDG 7.2) | C11: 1 | D11: Addressing Energy’s Interlinkages with other SDGs | E11: This document was prepared in support of the review of the SDGs at the United Nations High-Level Political Forum 2022. This edition takes a closer look at interlinkages between energy and SDG 4 (education), SDG 5 (gender), and SDG 15 (life on land), identifying potential indicators that could help in tracking global progress in these interlinkages. | F11: United Nations | G11: https://sdgs.un.org/publications/report-2022-sdg7-tag-policy-briefs-addressing-energys-interlinkages-other-sdgs-47727
A12: 1.2.2 | C12: 2 | D12: From goals to joules: A quantitative approach of interlinkages between energy and the Sustainable Development Goals | E12: This study aims to examine the complexity of the interconnections between energy and the SDGs, as well as give examples of how these linkages can be quantified. | F12: ScienceDirect | G12: https://www.sciencedirect.com/science/article/abs/pii/S2214629618308107
A13: 1.2.2 | C13: 3 | D13: Building a Nature-positive Energy Transformation - Why a Low-Carbon Economy is Better for People and Nature | E13: This report is builds on existing studies and quantifies and compares 30 environmental and socioeconomic impact metrics in two different energy scenarios for the future. It also presents a framework for establishing the nature-positive energy transformation that is essential to achieving critical climate and sustainable development goals. | F13: WWF | G13: https://wwf.panda.org/wwf_news/?9967866/Building-a-Nature-Positive-Energy-Transformation#:~:text=An%20energy%20system%20powered%20by,human%20health%2C%20biodiversity%20and%20ecosystems.
A14: 1.2.3 | B14: =VLOOKUP(A14,'ToC-old'!A:B,2,FALSE) -> Energy Efficiency (SDG 7.3) | C14: 1 | D14: Energy efficiency and sustainable development goals (SDGs) | E14: This study attempts to connect Sustainable Development Goals (SDGs) with energy efficiency for 20 Asian and Pacific (AP) countries using Data Envelopment Analysis (DEA) from 2000 to 2018. | F14: ScienceDirect | G14: https://www.sciencedirect.com/topics/economics-econometrics-and-finance/sustainable-development-goals
A15: 1.2.3 | C15: 2 | D15: Energy Efficiency 2024 | E15: Energy Efficiency 2024 is the IEA’s primary annual analysis on global energy efficiency developments, showing recent trends in energy intensity and demand, prices and policies. The report provides sector-specific analysis on buildings, appliances, industry and transport and explores system-wide themes such as electrification, flexibility, investment and employment. This report is launched in parallel with the new IEA Energy Efficiency Progress Tracker. | F15: IEA | G15: https://iea.blob.core.windows.net/assets/f304f2ba-e9a2-4e6d-b529-fb67cd13f646/EnergyEfficiency2024.pdf
A16: 1.2.3 | C16: 3 | D16: From Efficiency to Sustainability: Examining the Paradox of Digitalization of Energy | E16: The study aims to analyze the implementations and benefits of digital technologies across various aspects of the energy industry. It specifically discusses the impact of the digitalization of energy on achieving Sustainable Development Goals, highlighting the benefits and challenges it can bring. | F16: SPRINGER NATURE LINK | G16: https://link.springer.com/chapter/10.1007/978-3-031-68427-2_1
A17: 1.3.1 | B17: Approaches | C17: 1 | D17: Intersectionality Resource Guide and toolkit | E17: The “Intersectionality resource guide and toolkit”, a UN Women and United Nations Partnership on the Rights of Persons with Disabilities led collaborative initiative with support from United Nations and non-United Nations entities, aims to help both organizations and individual practitioners and experts to address intersectionality in policies and programmes. | F17: UNWOMEN | G17: https://www.unwomen.org/en/digital-library/publications/2022/01/intersectionality-resource-guide-and-toolkit
A18: 1.3.1 | C18: 2 | D18: Gender Mainstreaming: A Global Strategy for Achieving Gender Equality and the Empowerment of Women and Girls | E18: This brief sets a strategy for gender mainstreaming at programmatic and institutional levels to achieve transformative gender results. | F18: UNWOMEN | G18: https://www.unwomen.org/en/digital-library/publications/2020/04/brochure-gender-mainstreaming-strategy-for-achieving-gender-equality-and-empowerment-of-women-girls
A19: 1.3.1 | C19: 3 | D19: Leaving No One Behind: Equality and Non-Discrimination at the Heart of Sustainable Development | E19: This publication sets out a conceptual framework that includes equality (the imperative of moving towards substantive equality of opportunity and outcomes for all groups), non-discrimination and the broader concept of equity. | F19: United Nations | G19: https://unsceb.org/sites/default/files/imported_files/CEB%20equality%20framework-A4-web-rev3.pdf
A20: 1.3.2 | B20: Frameworks, Methods and Tools | C20: 1 | D20: Implementing the Water–Energy–Food–Ecosystems Nexus and Achieving the Sustainable Development Goals | E20: This publication compiles a number of case studies with the aim of highlighting the importance and benefits of the WEFE Nexus approach for development cooperation. It identifies pathways for a more integrated and sustainable use of resources that goes beyond traditional sector-specific development silos. | F20: UNESCO | G20: https://unesdoc.unesco.org/ark:/48223/pf0000379588
